Workbook
Name 넷: [1]점수표!$M$1:$M$4
Name 다섯: [1]점수표!$N$1:$N$5
Name 다섯다섯: [2]점수표!$N$1:$N$5
Name 둘: [1]점수표!$L$1:$L$2

Sheet 99.자체점검결과
B2: [ 금융회사 자체점검]
B4: 자동 계산 | I4: 필요시 입력 가능
B5: 자체점검 항목 | E5: 점검결과 | F5: 점검근거 | G5: 점검근거 | H5: 확인 필요 사항 | I5: 비고
B6: 1. 대표자 확인·서명 | E6: =IF(AND('0. 표지'!I8="O",'0. 표지'!N15="O"),"O","X") -> X | H6: =IF(E6="X",IF('0. 표지'!N15="O"," 파일 첨부 확인",IF('0. 표지'!I8="O","대표자 서명 확인"," 미기재 (0. 표지)"))) -> 미기재 (0. 표지)
B7: 2. 제출 기한 준수 | E7: =IF(COUNTA('1.개요'!$C$6:$C$7)=2,IF(AND('99.자체점검결과'!F7>='99.자체점검결과'!G7,'99.자체점검결과'!F7<='99.자체점검결과'!G7+2),"O","X"),"X") -> X | F7: =MONTH('1.개요'!$C$6) -> 1 | G7: =MOD('1.개요'!$C$7,12)+1 -> 1 | H7: =IF(COUNTA('1.개요'!$C$6:$C$7)<>2," 미기재 항목 존재 (1. 개요 - 제출일 또는 결산월)",IF($E$7="X"," 기한 미준수 사유 작성(비고)","")) -> 미기재 항목 존재 (1. 개요 - 제출일 또는 결산월)
B8: 3. 정보보호위원회 심의 의결 | E8: =IF(AND('1.개요'!$C$4>0,'1.개요'!$C$5="O"),"O","X") -> X | H8: =IF($E$8="X"," 미기재(오기재) 항목 존재(1. 개요 - 심의의결 관련)","") -> 미기재(오기재) 항목 존재(1. 개요 - 심의의결 관련)
B9: 4. 추진 목표 및 전략 | C9: 목표 | E9: =IF(F9>0,"O","X") -> X | F9: =COUNTA('2. 목표 및 전략'!$C$5:$C$9) -> 0 | H9: =IF($F$9=0," 미기재 (2. 목표 및 전략 - 추진 목표)","") -> 미기재 (2. 목표 및 전략 - 추진 목표)
C10: 전략 | E10: =IF(AND(F10>0,G10>0),"O","X") -> X | F10: =COUNTA('2. 목표 및 전략'!$C$14:$C$23) -> 0 | G10: =COUNTA('2. 목표 및 전략'!$D$14:$D$23) -> 0 | H10: =IF($F$10=0," 미기재 (2. 목표 및 전략 - 전략 내용) ","") & IF($G$10=0,"미기재 (2. 목표 및 전략 - 상세전략)","") -> 미기재 (2. 목표 및 전략 - 전략 내용) 미기재 (2. 목표 및 전략 - 상세전략)
B11: 5. 직전 연도 추진 실적 | E11: =IF($F$11>0,"O","X") -> X | F11: =SUM('3. 추진실적'!$J$5:$J$34) -> 0 | H11: =IF($F$11=0," 미기재 (3. 추진실적)","") -> 미기재 (3. 추진실적)
B12: 6. 당해 연도 추진 계획 | E12: =IF($F$12>0,"O","X") -> X | F12: =SUM('4. 추진계획'!$I$5:$I$34) -> 0 | H12: =IF($F$12=0," 미기재 (4. 추진계획)","") -> 미기재 (4. 추진계획)
B13: 7. 조직 등 운영 현황 | C13: 인력 현황 | D13: 작성여부 | E13: =IF($F$13=6,"O","X") -> X | F13: =SUM('5-1.인력현황'!$J$5:$J$21) -> 0 | H13: =IF($E$13="X"," 시트 내 미작성 항목 유무 확인","") -> 시트 내 미작성 항목 유무 확인
D14: 정보기술 부문 | E14: =IF('5-1.인력현황'!$C$11>0,"O","X") -> X | F14: ='5-1.인력현황'!$C$11/'5-1.인력현황'!$C$10*100 -> #DIV/0! | G14: 0.05 | H14: =IF('5-1.인력현황'!$C$11=0," 정보기술부문 인력 미입력","") -> 정보기술부문 인력 미입력
D15: 정보보호 부문 | E15: =IF('5-1.인력현황'!$C$12>0,"O","X") -> X | F15: ='5-1.인력현황'!$C$12/'5-1.인력현황'!$C$11*100 -> #DIV/0! | G15: 0.05 | H15: =IF('5-1.인력현황'!$C$12=0," 정보보호부문 인력 미입력","") -> 정보보호부문 인력 미입력
C16: CISO | D16: 임원여부 | E16: =IF(OR(F16="O",F16="X"),IF(G16="O",(IF(G16=F16,"적정","부적정")),"적정"),"X") -> X | F16: ='5-1.인력현황'!$F$17 -> 0 | G16: =IF(AND('5-1.인력현황'!$B$21>=20000,'5-1.인력현황'!$C$21>=300),"O","X") -> X | H16: =IF(ISBLANK('5-1.인력현황'!$F$17)," 임원 여부 미입력","") -> 임원 여부 미입력
D17: 겸직여부 | E17: =IF(OR(F17="O",F17="X"),IF(G17="X",(IF(G17=F17,"적정","부적정")),"적정"),"X") -> X | F17: ='5-1.인력현황'!$G$17 -> 0 | G17: =IF(AND('5-1.인력현황'!$B$21>=100000,'5-1.인력현황'!$C$21>=1000),"X","O") -> O | H17: =IF(ISBLANK('5-1.인력현황'!$G$17)," 겸직 여부 미입력","") -> 겸직 여부 미입력
C18: 조직도 | E18: =IF(AND('5-2. 조직도'!$C$5="O",'5-2. 조직도'!$D$5="O"),"O","X") -> X | H18: =IF($E$18="X"," 파일첨부여부 항목 확인") -> 파일첨부여부 항목 확인
C19: IT 인력 연수 계획 | E19: =IF($F$19>0,"O","X") -> X | F19: =SUM('5-3. IT인력 연수 계획'!$I$4:$I$33) -> 0 | H19: =IF(E19="X","연수계획 미수립 사유 작성(비고)","") -> 연수계획 미수립 사유 작성(비고)
B20: 8. 전년 및 금년 예산 | C20: 전년 예산 (배정액) | E20: =IF(AND('6.예산'!$D$4>0,'6.예산'!$D$5>0,'6.예산'!$D$15>0),"O","X") -> X
C21: 전년 예산 (집행액) | E21: =IF(AND('6.예산'!$E$4>0,'6.예산'!$E$5>0,'6.예산'!$E$15>0),"O","X") -> X
C22: 금년 예산 (배정액) | E22: =IF(AND('6.예산'!$G$4>0,'6.예산'!$G$5>0,'6.예산'!$G$15>0),"O","X") -> X | F22: ='6.예산'!$G$15/'6.예산'!$G$5*100 -> #DIV/0! | G22: 0.07
B24: ①주요 추진 목표 | I24: ⓐ키워드
B25: 목표 1 | C25: =IFERROR(VLOOKUP($B25,'2. 목표 및 전략'!$B$5:$C$9,2,0),"ERROR") -> 0
B26: 목표 2 | C26: =IFERROR(VLOOKUP($B26,'2. 목표 및 전략'!$B$5:$C$9,2,0),"ERROR") -> 0
B27: 목표 3 | C27: =IFERROR(VLOOKUP($B27,'2. 목표 및 전략'!$B$5:$C$9,2,0),"ERROR") -> 0
B29: ②주요 추진 전략 | I29: ⓐ키워드
B30: 전략 1 | C30: =IFERROR(VLOOKUP($B30,'2. 목표 및 전략'!$B$13:$C$23,2,0),"ERROR") -> 0
B31: 전략 2 | C31: =IFERROR(VLOOKUP($B31,'2. 목표 및 전략'!$B$13:$C$23,2,0),"ERROR") -> 0
B32: 전략 3 | C32: =IFERROR(VLOOKUP($B32,'2. 목표 및 전략'!$B$13:$C$23,2,0),"ERROR") -> 0
B34: 1. 자체 점검을 수행함으로써 정보기술부문계획서 작성의 충실도를 높이고자 하는 목적입니다.
B35: 2. 점검 결과 "X"로 표기되는 부문은 보고서상 누락사항이 없는지 재 확인 부탁드립니다.
B36: 3. 본 양식은 자동계산 양식입니다. (0.~7. sheet 내용에 따라 자동 반영)
B37: 4. 점검 결과가 "X"로 표기되는 경우 상세사유를 I열(비고)에 입력 부탁드립니다.
B38: 5. ①주요 추진 목표은 "2.목표 및 전략" sheet의 "1. 추진목표" 표에서 상위 3개가 자동 입력됩니다.
B39: 6. ②주요 추진 전략은 "2.목표 및 전략" sheet의 "2. 추진실적" 표에서 상위 3개가 자동 입력됩니다.
B40: 7. ⓐ 키워드의 경우 각각 주요 추진목표와 주요추진전략에 대한 키워드를 직접 입력 부탁드립니다.
B41: 예시) 리스크헤지, 금융보안교육강화, 인공지능 등

Sheet 0. 표지
A1: 0. 정보기술부문 계획서 표지
B3: ※ 정보기술부문 계획서 표지
I6: 1. 표지 첨부 여부
I7: 파일 첨부 여부
I13: 2. 대표자 확인 서명 여부
I14: 구분 | J14: 기관명 | K14: 부서 | L14: 직위 | M14: 성명 | N14: 서명여부 | O14: 전화번호 | P14: 이메일
I15: 대표이사
I16: 확인자
I17: 작성자
I22: ※ 유의사항(아래 사항을 반드시 준수하여 작성하여 주시기 바랍니다.)
I23: 1. 각 Sheet(동 표지 포함 8개 Sheet(0~7))의 유의사항을 반드시 확인하시고 작성하시기 바랍니다.
I24: 2. 대표이사(대표자) 등의 서명이 포함된 연간계획서 표지 사본(스캔본) 또는 대표이사(대표자)가 전자결재한 공문 사본(스캔본)을 반드시 별도 파일로 첨부하시기 바랍니다.
I25: (엑셀파일에 첨부시 불인정, 파일명 준수) * 파일명 : 정보기술부문 연간계획서 표지(회사명)
I26: 3. 왼쪽에 제시된 표지는 예시(작성안내 한글파일에 포함)이며, 각 회사의 사정 맞게 작성하여 스캔본을 별도 파일로 첨부(예시된 표지는 동 안내문서 한글 파일에 포함)

Sheet 1.개요
A1: 1. 정보기술부문 개요
B3: 1. 회사명
A4: * | B4: 2. 정보보호위원회 심의·의결일
B5: 2-1. 심의 의결 증빙 제출 여부
B6: 3. 제출일
B7: 4. 사업연도 결산월
A8: * | B8: 5. 대상기간(시작일)
A9: * | B9: 6. 대상기간(종료일)
B10: 7. 전자금융업무 수행 여부
B18: 8. 수행하는 전자금융업무
B29: ※ 유의사항(아래 사항을 반드시 준수하여 작성하여 주시기 바랍니다.)
B30: 1. 양식 절대 변경 불가
B31: 2. 2번, 5번, 6번은 반드시 연도·월·일을 "YYYY-MM-DD" 형식(숫자 8자리를 '-'기호로 구분)으로 작성(예시: 2021-01-01)
B32: 3. 2-1. 정보보호위원회 심의의결 증빙자료 제출 여부 (증빙을 반드시 별도 파일로 첨부하고, 파일명 준수)
B33: * 파일명 : 정보보호위원회 심의의결 증빙(회사명)
B34: 4. 4번은 사업연도 결산월을 01~12 중 선택
B35: 5. 7번은 전자금융거래법 제2조제1호 등을 참고하여 OX 중 선택(제출 대상 예외 여부는 전자금융거래법 제3조제3항 및 시행령 제5조제2항 등에 따라 판단)
B36: 6. (예시) 인터넷 뱅킹, 텔레뱅킹, 모바일 뱅킹 등

Sheet 2. 목표 및 전략
A1: 2. '23년도 정보기술부문 추진목표 및 추진전략
B3: 1. 추진 목표
B4: 구분 | C4: 목표 내용
B5: 목표 1
B6: 목표 2
B7: 목표 3
B8: 목표 4
B9: 목표 5
B12: 2. 추진 전략
B13: 구분 | C13: 전략 내용 | D13: 상세전략ⓐ | E13: 상세전략ⓑ | F13: 상세전략ⓒ | G13: 상세전략ⓓ
B14: 전략 1
B15: 전략 2
B16: 전략 3
B17: 전략 4
B18: 전략 5
B19: 전략 6
B20: 전략 7
B21: 전략 8
B22: 전략 9
B23: 전략 10
B26: ※ 유의사항(아래 사항을 반드시 준수하여 작성하여 주시기 바랍니다.)
B27: 1. 목표 및 전략이 5~10행을 초과하는 경우는 중점 목표(5개), 전략(10개)만 본 시트에 작성하고, 그 외는 별도 파일로 제출
... B31: 1. 추진 목표
B32: 구분 | C32: 목표 내용
B33: 목표 1 | C33: (예) 혁신을 주도하는, Creative IT 그룹
B35: 2. 추진 전략
B36: 구분 | C36: 전략 내용 | D36: 상세전략ⓐ | E36: 상세전략ⓑ | F36: 상세전략ⓒ | G36: 상세전략ⓓ
B37: 전략 1 | C37: (예) IT시스템 안정성 확보 | D37: (예) 무결점 시스템 구현 | E37: (예) 디지털 금융서비스 강화 | F37: (예) 노후 IT기기 교체
B38: 전략 2 | C38: (예) 최적화된 인프라 구축 | D38: (예) 영업지원 강화 | E38: (예) 글로벌 인프라 구축
B40: 본 (예시)는 이해를 돕기위한 예시일뿐이며 실제 내용은 각 회사 사정에 맞게 적의 판단하여 작성

Sheet 3. 추진실적
A1: 3. 정보기술부문 '22년도 추진 실적
B3: ①구분 | C3: ②'22년도 계획 포함 여부 | D3: ③사업범위 | E3: ④사업명 | F3: ⑤수행기간(예정) | H3: ⑥상세추진내용 | I3: ⑦이행여부
F4: 시작년월 | G4: 종료년월 | J4: 검증
J5: =IF(COUNTA($B5:$I5)=8,1,0) -> 0
J6: =IF(COUNTA($B6:$I6)=8,1,0) -> 0
J7: =IF(COUNTA($B7:$I7)=8,1,0) -> 0
J8: =IF(COUNTA($B8:$I8)=8,1,0) -> 0
J9: =IF(COUNTA($B9:$I9)=8,1,0) -> 0
J10: =IF(COUNTA($B10:$I10)=8,1,0) -> 0
J11: =IF(COUNTA($B11:$I11)=8,1,0) -> 0
J12: =IF(COUNTA($B12:$I12)=8,1,0) -> 0
J13: =IF(COUNTA($B13:$I13)=8,1,0) -> 0
J14: =IF(COUNTA($B14:$I14)=8,1,0) -> 0
J15: =IF(COUNTA($B15:$I15)=8,1,0) -> 0
J16: =IF(COUNTA($B16:$I16)=8,1,0) -> 0
... J34: =IF(COUNTA($B34:$I34)=8,1,0) -> 0
B37: ※ 유의사항(아래 사항을 반드시 준수하여 작성하여 주시기 바랍니다.)
B38: 1. '①구분'은 정보기술 / 정보보안 중 선택
B39: 2. '② 22년도 정보기술부문 계획서 상 추진계획에 포함 여부
B40: 3. '③사업범위'는 '(참고)사업 키워드' 시트를 참고하되, 내용은 각 회사별로 적의판단하여 작성
B41: 4. '⑤수행기간(예정)'의 시작년월과 종료년월은 반드시 "OO년OO월" 형식으로 작성(예시: 19년03월)
B42: 5. '⑦이행여부'는 완료 / 진행중 / 미착수 / 폐기 중 선택
B43: 5-1. 미착수 : 22년도 계획에 포함되어 있으나 계획이 미루어져 미착수 상태 (23년 계획에 포함) / 폐기 : 22년도 계획에 포함되어 있으나, 진행하지 않기로 함
B44: 6. 추진실적이 30행을 초과하는 경우는 주요 실적(30개)만 본 시트에 작성하고, 그 외는 별도 파일로 제출
B46: (예시)
B48: ①구분 | C48: ②'22년도 계획 포함 여부 | D48: ③사업범위 | E48: ④사업명 | F48: ⑤수행기간(예정) | H48: ⑥상세추진내용 | I48: ⑦이행여부
F49: 시작년월 | G49: 종료년월
B50: 정보기술 | C50: O | D50: 핀테크 도입 | E50: 디지털 플랫폼 구축 | F50: 22년01월 | G50: 23년03월 | H50: 혁신적 플랫폼 구축을 통한 디지털라이제이션 달성 | I50: 진행중
B53: 본 (예시)는 이해를 돕기위한 예시일뿐이며 실제 내용은 각 회사 사정에 맞게 적의 판단하여 작성

Sheet 4. 추진계획
A1: 4. 정보기술부문 '23년도 추진 계획
B3: ①구분 | C3: ②사업범위 | D3: ③사업명 | E3: ④수행기간(예정) | G3: ⑤상세추진내용 | H3: ⑥비고
E4: 시작년월 | F4: 종료년월 | I4: 검증
I5: =IF(COUNTA(B5:H5)>=6,1,0) -> 0
I6: =IF(COUNTA(B6:H6)>=6,1,0) -> 0
I7: =IF(COUNTA(B7:H7)>=6,1,0) -> 0
I8: =IF(COUNTA(B8:H8)>=6,1,0) -> 0
I9: =IF(COUNTA(B9:H9)>=6,1,0) -> 0
I10: =IF(COUNTA(B10:H10)>=6,1,0) -> 0
I11: =IF(COUNTA(B11:H11)>=6,1,0) -> 0
I12: =IF(COUNTA(B12:H12)>=6,1,0) -> 0
I13: =IF(COUNTA(B13:H13)>=6,1,0) -> 0
I14: =IF(COUNTA(B14:H14)>=6,1,0) -> 0
I15: =IF(COUNTA(B15:H15)>=6,1,0) -> 0
I16: =IF(COUNTA(B16:H16)>=6,1,0) -> 0
... I34: =IF(COUNTA(B34:H34)>=6,1,0) -> 0
B37: ※ 유의사항(아래 사항을 반드시 준수하여 작성하여 주시기 바랍니다.)
B38: 1. '①구분'은 정보기술 / 정보보안 중 선택
B39: 2. '②사업범위'는 (참고) 시트를 참고하되, 내용은 각 회사별로 적의판단하여 작성
B40: 3. '④수행기간(예정)'의 시작년월과 종료년월은 반드시 "OO년OO월" 형식으로 작성(예시: 19년03월)
B41: 4. '⑥비고'는 완료 / 진행중 / 미착수 중 선택
B42: 5. 추진계획이 30행을 초과하는 경우는 주요 추진계획(30개)만 본 시트에 작성하고, 그 외는 별도 파일로 제출
B44: (예시)
B46: ①구분 | C46: ②사업범위 | D46: ③사업명 | E46: ④수행기간(예정) | G46: ⑤상세추진내용 | H46: ⑥비고
E47: 시작년월 | F47: 종료년월
B48: 정보기술 | C48: 핀테크 도입 | D48: 디지털 플랫폼 구축 | E48: 23년01월 | F48: 25년03월 | G48: 혁신적 플랫폼 구축을 통한 디지털라이제이션 달성 | H48: 진행중
B51: 본 (예시)는 이해를 돕기위한 예시일뿐이며 실제 내용은 각 회사 사정에 맞게 적의 판단하여 작성

Sheet 5-1.인력현황
A1: 5-1. 정보기술부문 인력현황(현황)
B3: 1. 인력현황 작성 기준일 | J3: 검증
B4: ①기준일
J5: =IF(COUNTA(B5)=1,1,0) -> 0
B7: 2. 인력현황 : 총임직원, 정보기술부문 및 정보보호부문 현황
B8: 구분 | C8: 인원(ⓐ+ⓑ+ⓒ+ⓓ) | D8: 내부인력 | F8: 외주인력 | I8: 비고
D9: 정규직ⓐ | E9: 계약직ⓑ | F9: 전산 자회사ⓒ | G9: 인정 상주ⓓ | H9: 기타
B10: ②총임직원(단위 : 명) | J10: =IF(C10>0,1,0) -> 0
B11: ③정보기술부문(단위 : 명) | C11: =SUM(D11:G11) -> 0 | J11: =IF(C11>0,1,0) -> 0
B12: ④정보보호부문(단위 : 명) | C12: =SUM(D12:G12) -> 0 | J12: =IF(C12>0,1,0) -> 0
B14: 3. 인력현황 : CIO 및 CISO 지정 현황
B15: 구분 | C15: 성명 | D15: 소속 | E15: 직급(직책) | F15: 임원여부 | G15: 겸직여부 | H15: 비고
B16: ⑤CIO현황
B17: ⑥CISO현황 | J17: =IF(COUNTA($C$17:$G$17)=5,1,0) -> 0
B19: 4. CISO의 임원지정 및 겸직금직 필수여부 판단 근거(전자금융거래법 시행령 제11조의3 관련)
B20: ⑦총자산(단위 : 억원) | C20: ⑧상시 종업원 수(단위 : 명) | D20: 비고
J21: =IF(COUNTA(B21:C21)=2,1,0) -> 0
B23: ※ 유의사항(아래 사항을 반드시 준수하여 작성하여 주시기 바랍니다.)
B24: 1. '①기준일'은 반드시 연도·월·일을 "YYYY-MM-DD" 형식(숫자 8자리를 '-'기호로 구분)으로 작성(예시: 2022-01-01)
B25: 2. '②총임직원'은 회사 전체 임직원 수를 작성
B26: 3. '⑤CIO현황'과 '⑥CISO현황'의 '임원여부' 및 '겸직여부'는 ○ / X 중 선택하고, '겸직여부'는 CISO의 CIO 겸직여부로 판단하며, 작성에 관한 사항은 전자금융거래법 제21조의2 등을 참조
B27: 4. '⑦총자산' 및 '⑧상시 종업원 수'는 직전 사업연도 말을 기준으로 하며, 작성에 관한 사항은 전자금융거래법 시행령 제11조의3 등을 참조
B28: 5. 전자금융업무보고서(IT017 - 정보기술 및 정보보호부문 인력현황 참조) 작성 기준과 동일하게 작성
B29: 5-1. 정규직ⓐ = IT017 정규직(①)
B30: 5-2. 계약직ⓑ = IT017 계약직(②)
B31: 5-3. 전산 자회사ⓒ = IT017 전산자회사 상주인력 (⑧=③+④)
B32: 5-4. 인정 상주ⓓ = IT017 인정 상주 외주인력(⑨)

Sheet 5-2. 조직도
A1: 5-2. 정보기술부문 인력현황(조직도)
B3: 1. 인력현황(조직도) 작성 기준
B4: ①기준일 | C4: 작성 여부 | D4: 파일 첨부 여부
B25: ※ 유의사항(아래 사항을 반드시 준수하여 작성하여 주시기 바랍니다.)
B26: 1. '①기준일'은 반드시 연도·월·일을 "YYYY-MM-DD" 형식(숫자 8자리를 '-'기호로 구분)으로 작성(예시: 2022-01-01)
B27: 2. 위 조직도는 이해를 돕기위한 예시일뿐이며, 실제 내용은 각 회사 사정에 맞게 스캔본을 별도 파일로 첨부 (엑셀파일에 첨부시 불인정)
B28: * 파일명 : 정보기술부문 인력현황 조직도(회사명)

Sheet 5-3. IT인력 연수 계획
A1: 5-3. '23년도 전산 관련 교육 및 연수프로그램 운영 계획
B3: ①구분 | C3: ②연수대상 | D3: ③연수명 | E3: ④연수방식 | F3: ⑤필수여부 | G3: ⑥이수시간 (단위 : 시간) | H3: ⑥비고 | I3: 검증
I4: =IF(COUNTA(B4:H4)>=6,1,0) -> 0
I5: =IF(COUNTA(B5:H5)>=6,1,0) -> 0
I6: =IF(COUNTA(B6:H6)>=6,1,0) -> 0
I7: =IF(COUNTA(B7:H7)>=6,1,0) -> 0
I8: =IF(COUNTA(B8:H8)>=6,1,0) -> 0
I9: =IF(COUNTA(B9:H9)>=6,1,0) -> 0
I10: =IF(COUNTA(B10:H10)>=6,1,0) -> 0
I11: =IF(COUNTA(B11:H11)>=6,1,0) -> 0
I12: =IF(COUNTA(B12:H12)>=6,1,0) -> 0
I13: =IF(COUNTA(B13:H13)>=6,1,0) -> 0
I14: =IF(COUNTA(B14:H14)>=6,1,0) -> 0
I15: =IF(COUNTA(B15:H15)>=6,1,0) -> 0
... I33: =IF(COUNTA(B33:H33)>=6,1,0) -> 0
B36: ※ 유의사항(아래 사항을 반드시 준수하여 작성하여 주시기 바랍니다.)
B37: 1. "6.예산" sheet "정보기술 교육, 훈련비" 및 "정보보호 교육 훈련비" 항목에 예산 편성 또는 집행된 교육 및 연수에 한정하여 기재 요망,
B38: 근거규정은 전자금융감독규정 제8조 제1항 제3호를 참조
B39: 2. '① 구분' 은 연수 목적에 따라 '정보기술' 과 '정보보호'로 구분
B40: 3. '② 연수대상 : 전직원 / 정보기술인력 / 정보보호인력 중 택
B41: 4. '④ 연수방식 : 내부(내부강사 활용), 외부(외부 교육 전문기관 등)
B42: 5. '⑤ 필수여부 : 필수/선택 중 택1
B43: 6. 작성 대상 교육 및 연수 계획이 30행을 초과하는 경우 주요 계획(30개)만 적시

Sheet 6.예산
A1: 6. 정보기술부문의 직전('22년) 및 당해 연도('23년) 예산
B3: 구분 | D3: ⓐ'22년도 예산 편성액 (단위 : 천원) | E3: ⓑ22년도 예산 집행액 (단위 : 천원) | F3: 집행률 (ⓑ/ⓐ%) | G3: ⓒ'23년도 예산 편성액 (단위 : 천원) | H3: 증감률 ((ⓒ-ⓐ)/ⓐ%) | I3: 검증
B4: ①총예산 | F4: =IF($D4=0,"",$E4/$D4) | H4: =IF($D4=0,"",($G4-$D4)/$D4) | I4: =IF(COUNTA($D4:$H4)>=3,1,0) -> 0
B5: ②정보기술 관련 예산 | D5: =SUM(D$6:D$14) -> 0 | E5: =SUM(E$6:E$14) -> 0 | F5: =IF($D5=0,"",$E5/$D5) | G5: =SUM(G$6:G$14) -> 0 | H5: =IF($D5=0,"",($G5-$D5)/$D5) | I5: =IF(COUNTA($D5:$H5)>=3,1,0) -> 1
B6: ③ 정보기술 관련 예산 상세내역 | C6: 정보기술관련 인건비 | F6: =IF($D6=0,"",$E6/$D6) | H6: =IF($D6=0,"",($G6-$D6)/$D6) | I6: =IF(COUNTA($D6:$H6)>=3,1,0) -> 0
C7: 정보처리시스템 구입비 및 임차료 | F7: =IF($D7=0,"",$E7/$D7) | H7: =IF($D7=0,"",($G7-$D7)/$D7) | I7: =IF(COUNTA($D7:$H7)>=3,1,0) -> 0
C8: 정보처리시스템 유지보수비 | F8: =IF($D8=0,"",$E8/$D8) | H8: =IF($D8=0,"",($G8-$D8)/$D8) | I8: =IF(COUNTA($D8:$H8)>=3,1,0) -> 0
C9: 정보기술 서비스 이용료 | F9: =IF($D9=0,"",$E9/$D9) | H9: =IF($D9=0,"",($G9-$D9)/$D9) | I9: =IF(COUNTA($D9:$H9)>=3,1,0) -> 0
C10: 정보기술 외주 용역비 | F10: =IF($D10=0,"",$E10/$D10) | H10: =IF($D10=0,"",($G10-$D10)/$D10) | I10: =IF(COUNTA($D10:$H10)>=3,1,0) -> 0
C11: 정보기술 컨설팅 비용 | F11: =IF($D11=0,"",$E11/$D11) | H11: =IF($D11=0,"",($G11-$D11)/$D11) | I11: =IF(COUNTA($D11:$H11)>=3,1,0) -> 0
C12: 정보기술 교육, 훈련비 | F12: =IF($D12=0,"",$E12/$D12) | H12: =IF($D12=0,"",($G12-$D12)/$D12) | I12: =IF(COUNTA($D12:$H12)>=3,1,0) -> 0
C13: 통신회선 이용료 | F13: =IF($D13=0,"",$E13/$D13) | H13: =IF($D13=0,"",($G13-$D13)/$D13) | I13: =IF(COUNTA($D13:$H13)>=3,1,0) -> 0
C14: 기타 | F14: =IF($D14=0,"",$E14/$D14) | H14: =IF($D14=0,"",($G14-$D14)/$D14) | I14: =IF(COUNTA($D14:$H14)>=3,1,0) -> 0
B15: ④정보보호 관련 예산 | D15: =SUM(D$16:D$24) -> 0 | E15: =SUM(E$16:E$24) -> 0 | F15: =IF($D15=0,"",$E15/$D15) | G15: =SUM(G$16:G$24) -> 0 | H15: =IF($D15=0,"",($G15-$D15)/$D15) | I15: =IF(COUNTA($D15:$H15)>=3,1,0) -> 1
B16: ⑤ 정보보호 관련 예산 상세내역 | C16: 정보보호관련 인건비 | F16: =IF($D16=0,"",$E16/$D16) | H16: =IF($D16=0,"",($G16-$D16)/$D16) | I16: =IF(COUNTA($D16:$H16)>=3,1,0) -> 0
C17: 정보보호시스템 구입비 및 임차료 | F17: =IF($D17=0,"",$E17/$D17) | H17: =IF($D17=0,"",($G17-$D17)/$D17) | I17: =IF(COUNTA($D17:$H17)>=3,1,0) -> 0
C18: 정보보호시스템 유지보수비 | F18: =IF($D18=0,"",$E18/$D18) | H18: =IF($D18=0,"",($G18-$D18)/$D18) | I18: =IF(COUNTA($D18:$H18)>=3,1,0) -> 0
C19: 정보보호서비스 이용료 | F19: =IF($D19=0,"",$E19/$D19) | H19: =IF($D19=0,"",($G19-$D19)/$D19) | I19: =IF(COUNTA($D19:$H19)>=3,1,0) -> 0
C20: 정보보호 관련 외주 용역비 | F20: =IF($D20=0,"",$E20/$D20) | H20: =IF($D20=0,"",($G20-$D20)/$D20) | I20: =IF(COUNTA($D20:$H20)>=3,1,0) -> 0
C21: 정보보호 관련 컨설팅 비용 | F21: =IF($D21=0,"",$E21/$D21) | H21: =IF($D21=0,"",($G21-$D21)/$D21) | I21: =IF(COUNTA($D21:$H21)>=3,1,0) -> 0
C22: 정보보호 관련 교육, 훈련비 | F22: =IF($D22=0,"",$E22/$D22) | H22: =IF($D22=0,"",($G22-$D22)/$D22) | I22: =IF(COUNTA($D22:$H22)>=3,1,0) -> 0
C23: 정보보호 관련 통신회선 이용료 | F23: =IF($D23=0,"",$E23/$D23) | H23: =IF($D23=0,"",($G23-$D23)/$D23) | I23: =IF(COUNTA($D23:$H23)>=3,1,0) -> 0
C24: 기타 | F24: =IF($D24=0,"",$E24/$D24) | H24: =IF($D24=0,"",($G24-$D24)/$D24) | I24: =IF(COUNTA($D24:$H24)>=3,1,0) -> 0
B25: 정보보호 관련 예산 비율 | D25: =D$15/D$5 -> #DIV/0! | F25: =IF($E25=0,0,$E25/$D25) -> 0 | G25: =G$15/G$5 -> #DIV/0!
B27: ※ 유의사항(아래 사항을 반드시 준수하여 작성하여 주시기 바랍니다.)
B28: 1. 직전연도 예산은 '편성'액과 '집행'액을 구분하여 작성 요망
B29: 2. '③정보기술 관련 예산 상세내역' 및 '⑤정보보호 관련 예산 상세내역'을 반드시 작성 요망(총액만 작성하지 말것)
B30: 3. 금액 단위(천원)를 준수하여 작성 요망
B31: 4. 전자금융업무보고서(IT018 - 정보기술 및 정보보호부문 예산현황 참조) 작성 기준과 동일하게 작성

Sheet (참고)사업 키워드
A1: 분류(예) | B1: 사업 키워드(예)
A2: 법규준수 | B2: 법규준수 | D2: ※ 유의사항(아래 사항을 반드시 준수하여 작성하여 주시기 바랍니다.)
B3: 제도 변경 및 전산시스템 개발 지원 | D3: 1. 동 사업 키워드 분류는 이해를 돕기위한 예시일뿐이며 실제 내용은 각 회사 사정에 맞게 적의 판단하여 작성
B4: IFRS9 도입 관련사업
B5: 기타 법규 준수 및 대응 관련
A6: 보안강화 | B6: 고객정보 보호
B7: 보안시스템 강화
B8: 보안취약점 대응
B9: 보안의식 고취
B10: 내부통제 강화
B11: 취약점 점검 및 보완
B12: 정보보호 환경 개선
B13: 보안사고 방지
B14: 안정성과 보안성 설계
B15: 취약점 진단
B16: 개인정보보호 지속적인 체계마련
B17: 보안운영업무 선진화
B18: 인프라 품질 개선 및 보안강화
... B29: 정보보안 및 개인정보에 대한 중요성 인지
A30: 인프라, 시스템 개선 | B30: 노후장비교체
B31: Win11 업그레이드
B32: 자금세탁방지시스템 고도화(RBA)
B33: AML시스템구축
B34: FDS고도화
B35: IFRS9 도입
B36: 자동화기기 도입
B37: 사무기기 도입(고속 스캐너 등)
B38: 서버 등 인프라 기기 교체 및 증설
B39: MTS시스템 업그레이드
B40: 원장처리 속도튜닝 등 개선
B41: 접속시스템 재개발
A42: 영업지원(예) (업무 효율, 비용 절감, 고객만족도 제고) | B42: 인터넷, 모바일 시스템 고도화
B43: 업무지원시스템 고도화
B44: IT서비스 지원 강화
B45: 업무 효율성 제고
B46: 오퍼레이션 지원 강화
B47: 표준화 시스템
B48: 업무 환경 및 제도 개선
B49: 기술을 활용하여 성능 향상
B50: 제도 변경 및 전산시스템 개발 지원
...
