Workbook

Sheet 표지
A1: =_xlfn.CONCAT(YEAR(O1),"년 ",MONTH(O1),"월호 울산지역 주요경제통계") -> 2026년 4월호 울산지역 주요경제통계 | N1: 날짜 | O1: 46113
A3: 1. 통계 전반에 걸쳐서 사용된 기호의 뜻은 다음과 같음
A5: [ 0 ] | B5: 단위미만(0포함)
A6: [ - ] | B6: 해당사항 없음
A7: [ .. ] | B7: 미상
A8: [ r ] | B8: 정정
A9: [ p ] | B9: 잠정치
A10: [ Δ ] | B10: 시계열의 비연속: 이 기호가 붙은 숫자의 경우 그 이후와 이전의 시계열은 직접 비교할 수 없음
A12: 2. 모든 통계는 합계와 세목이 각각 반올림되었으므로 세목의 합계가 "합계"와 일치하지 않을 수 있음
A14: 3. 통계표 중 전월호의 수치와 일치하지 않는 통계는 최근호에서 정정된 것으로 최근호가 정확함
A16: 4. 울산지역 금융통계상의 금융기관 포괄범위
A17: 가. 예금은행
A18: (1) 일반은행 : 시중은행, 지방은행
A19: (2) 특수은행 : 기업은행, 농협은행, 수협은행, 산업은행
A21: 나. 비은행금융기관
A22: o 한국수출입은행
A23: o 종합금융회사
A24: o 집합투자업자, 신탁업자, 상호저축은행
A25: o 신용협동기구(상호금융, 새마을금고, 신용협동조합)
A26: o 우체국
... A34: 8. 『2024.6월호 울산지역 경제동향』부터 "개인 신용카드 판매액" 통계 제공을 중단하며, 『2024.7월호 울산지역 경제동향』부터 『울산지역 주요경제통계』를 엑셀파일로 제공

Sheet 1.1. 한국은행 계정
A1: 울산지역 주요경제통계
A3: Ⅰ- 1. 금융통계
A5: 1. 한국은행 계정
A6: (울산본부) | G6: (억원)
A7: 연월말 | B7: 화폐 발행 및 환수 | D7: 예금 및 대출금 | F7: 국고 세입 및 세출
B8: 발행 | C8: 환수 | D8: 예금 | E8: 대출금 | F8: 세입 | G8: 세출
A11: 40544 | B11: 12248 | C11: 3937 | D11: 599 | E11: 1401 | F11: 182035 | G11: 4745
A12: =DATE(YEAR(A11)+1,MONTH(A11),1) -> 40909 | B12: 1896 | C12: 769 | D12: 670 | E12: 1401 | F12: 186539 | G12: 4998
A13: =DATE(YEAR(A12)+1,MONTH(A12),1) -> 41275 | B13: 132 | C13: 132 | D13: 731 | E13: 1401 | F13: 197915 | G13: 5587
A14: =DATE(YEAR(A13)+1,MONTH(A13),1) -> 41640 | B14: 162 | C14: 162 | D14: 674 | E14: 1649 | F14: 177874 | G14: 6053
A15: =DATE(YEAR(A14)+1,MONTH(A14),1) -> 42005 | B15: 191 | C15: 190 | D15: 631 | E15: 1649 | F15: 153147 | G15: 5828
A16: =DATE(YEAR(A15)+1,MONTH(A15),1) -> 42370 | B16: 206 | C16: 206 | D16: 706 | E16: 1649 | F16: 159178 | G16: 6968
A17: =DATE(YEAR(A16)+1,MONTH(A16),1) -> 42736 | B17: 203 | C17: 203 | D17: 812 | E17: 1649 | F17: 183259 | G17: 7205
A18: =DATE(YEAR(A17)+1,MONTH(A17),1) -> 43101 | B18: 213 | C18: 213 | D18: 794 | E18: 1649 | F18: 191119 | G18: 6647
A19: =DATE(YEAR(A18)+1,MONTH(A18),1) -> 43466 | B19: 219 | C19: 219 | D19: 1092 | E19: 1649 | F19: 183483 | G19: 6938
A20: =DATE(YEAR(A19)+1,MONTH(A19),1) -> 43831 | B20: 216 | C20: 216 | D20: 583 | E20: 4049 | F20: 150307 | G20: 8089
A21: =DATE(YEAR(A20)+1,MONTH(A20),1) -> 44197 | B21: 248 | C21: 248 | D21: 660 | E21: 4012 | F21: 183024 | G21: 8914
A22: =DATE(YEAR(A21)+1,MONTH(A21),1) -> 44562 | B22: 101 | C22: 101 | D22: 1092 | E22: 4049 | F22: 211052 | G22: 9468
A23: =DATE(YEAR(A22)+1,MONTH(A22),1) -> 44927 | B23: 72 | C23: 72 | D23: 875 | E23: 1649 | F23: 172096 | G23: 8698
... A25: =DATE(YEAR(A24)+1,MONTH(A24),1) -> 45658 | B25: 67 | C25: 67 | D25: 1022 | E25: 5137 | F25: 194439 | G25: 9775
A27: =DATE(YEAR(표지!O1)-2,MONTH(표지!O1)-1,1) -> 45352 | B27: 4 | C27: 4 | D27: 1169 | E27: 1649 | F27: 2945 | G27: 699
A28: =DATE(YEAR(A27),MONTH(A27)+1,1) -> 45383 | B28: 4 | C28: 4 | D28: 1068 | E28: 2200 | F28: 24996 | G28: 596
A29: =DATE(YEAR(A28),MONTH(A28)+1,1) -> 45413 | B29: 3 | C29: 3 | D29: 1132 | E29: 3304 | F29: 12550 | G29: 538
A30: =DATE(YEAR(A29),MONTH(A29)+1,1) -> 45444 | B30: 3 | C30: 3 | D30: 1265 | E30: 3897 | F30: 7512 | G30: 822
A31: =DATE(YEAR(A30),MONTH(A30)+1,1) -> 45474 | B31: 3 | C31: 3 | D31: 1063 | E31: 3897 | F31: 24438 | G31: 672
A32: =DATE(YEAR(A31),MONTH(A31)+1,1) -> 45505 | B32: 3 | C32: 3 | D32: 1112 | E32: 3897 | F32: 7106 | G32: 562
A33: =DATE(YEAR(A32),MONTH(A32)+1,1) -> 45536 | B33: 14 | C33: 14 | D33: 1340 | E33: 3897 | F33: 20316 | G33: 585
A34: =DATE(YEAR(A33),MONTH(A33)+1,1) -> 45566 | B34: 3 | C34: 3 | D34: 1163 | E34: 3897 | F34: 18354 | G34: 474
A35: =DATE(YEAR(A34),MONTH(A34)+1,1) -> 45597 | B35: 3 | C35: 3 | D35: 1124 | E35: 3897 | F35: 5197 | G35: 495
A36: =DATE(YEAR(A35),MONTH(A35)+1,1) -> 45627 | B36: 3 | C36: 3 | D36: 978 | E36: 3897 | F36: 20065 | G36: 1348
A38: =DATE(YEAR(A36),MONTH(A36)+1,1) -> 45658 | B38: 18 | C38: 18 | D38: 1506 | E38: 3897 | F38: 20358 | G38: 637
A39: =DATE(YEAR(A38),MONTH(A38)+1,1) -> 45689 | B39: 3 | C39: 3 | D39: 1356 | E39: 1356 | F39: 12600 | G39: 823
A40: =DATE(YEAR(A39),MONTH(A39)+1,1) -> 45717 | B40: 3 | C40: 3 | D40: 1141 | E40: 5137 | F40: 10422 | G40: 695
A41: =DATE(YEAR(A40),MONTH(A40)+1,1) -> 45748 | B41: 4 | C41: 4 | D41: 1203 | E41: 5137 | F41: 19140 | G41: 586
A42: =DATE(YEAR(A41),MONTH(A41)+1,1) -> 45778 | B42: 3 | C42: 3 | D42: 1407 | E42: 5137 | F42: 7056 | G42: 669
A43: =DATE(YEAR(A42),MONTH(A42)+1,1) -> 45809 | B43: 3 | C43: 3 | D43: 1213 | E43: 5137 | F43: 19695 | G43: 795
A44: =DATE(YEAR(A43),MONTH(A43)+1,1) -> 45839 | B44: 4 | C44: 4 | D44: 1580 | E44: 5137 | F44: 18135 | G44: 743
A45: =DATE(YEAR(A44),MONTH(A44)+1,1) -> 45870 | B45: 3 | C45: 3 | D45: 1565 | E45: 5137 | F45: 5067 | G45: 545
A46: =DATE(YEAR(A45),MONTH(A45)+1,1) -> 45901 | B46: 10 | C46: 10 | D46: 1719 | E46: 5055 | F46: 22737 | G46: 571
A47: =DATE(YEAR(A46),MONTH(A46)+1,1) -> 45931 | B47: 7 | C47: 7 | D47: 1270 | E47: 5137 | F47: 21375 | G47: 521
...

Sheet 1.2~3.여수신 등
A1: 2.예금은행 여수신 | K1: 2. 예금은행 여수신 | AB1: 2. 예금은행 여수신 | AP1: 2. 예금은행 여수신 | AX1: 2. 예금은행 여수신 | BF1: 2. 예금은행 여수신 | BP1: 2. 예금은행 여수신 | CB1: 3.비은행예금취급기관 여수신 | CK1: 13. 비은행예금취급기관 | CS1: 13. 비은행예금취급기관
AB2: 2.2 예금은행 대출금 | AP2: 2.2.2. 주체별 및 용도별 대출금 | AX2: 2.2.3. 기업자금 대출금 | CK2: 3.2 비은행예금취급기관1) 여신
A3: 2.1 예금은행 수신 | AB3: 2.2.1 자금별 대출금 | AP3: (울산) | AW3: (억원) | AX3: (울산) | BE3: (억원) | BF3: 2.2.4 산업별 대출금1)2) | CB3: 3.1 비은행예금취급기관1) 수신 | CK3: 3.2.1 기관별 여신 | CS3: 3.2.2 차입주체별 여신
A4: (울산) | J4: (억원) | K4: (울산) | S4: (억원) | T4: (울산) | AA4: (억원) | AB4: (울산) | AO4: (억원) | AP4: 연월말 | AQ4: 총대출금 | AR4: 주체별 | AV4: 용도별 | AX4: 연월말 | AY4: 총대출금 | AZ4: 기업자금 대출금 | BE4: 중소기업 대출비중1) | BF4: (울산) | CA4: (억원) | CB4: (울산) | CJ4: (억원) | CK4: (울산) | CR4: (억원) | CS4: (울산) | CX4: (억원)
A5: 연월말 | B5: 총수신1) | C5: 예 금 | F5: 시장성 수신 | K5: 연월말 | L5: 총예금 | M5: 요 구 불 예 금 | T5: 저 축 성 예 금 | AB5: 연월말 | AC5: 총대출금 | AD5: 금융자금 | AO5: 재정자금4) | AR5: 기업 | AS5: 가계 | AU5: 공공 및 기타1) | AV5: 운전자금 | AW5: 시설자금 | AZ5: 소계 | BA5: 대기업 | BB5: 중소기업 | BF5: 연월말 | BG5: 산업별 대출금 | BP5: 산업별 대출금 | BZ5: 가계대출 | CA5: 대출금 총계 | CB5: 연월말 | CK5: 연월말 | CS5: 연월말 | CT5: 기업1) | CW5: 가계2)
C6: 소계 | D6: 요구불예금 | E6: 저축성예금 | F6: 소계 | G6: CD | H6: 금융채 | I6: 매출어음 | J6: RP | M6: 소 계 | N6: 당좌예금 | O6: 가계당좌예금 | P6: 보통예금 | Q6: 별단예금 | R6: 공공예금 | S6: 기 타1) | T6: 소 계 | U6: 정기예금 | V6: 정기적금 | W6: 저축예금 | X6: 기업자유예금 | Y6: 수입부금 | Z6: 주택부금 | AA6: 기 타2) | AD6: 소계 | AE6: 일반자금1) | AF6: 주택관련 대출2) | AG6: 무역금융 | AH6: 외상매출 채권담보 | AI6: 중소기업 자금3) | AJ6: 기업구매자금 | AK6: 할인어음 | AL6: 농업자금 | AM6: 당좌대출 | AN6: 기타 | AT6: (주택담보대출) | BC6: 운전자금 | BD6: 시설자금 | BG6: 산업대출금 합계 | BH6: 제조업 소계 | BI6: 제조업 시설자금 | BJ6: 석유화학 | BK6: 제1차금속 | BL6: 금속가공 | BM6: 기계장비 | BN6: 자동차 | BO6: 조선 및 기타 운송 | BP6: 비제조업 소계1) | BQ6: 농림어업 | BR6: 광업 | BS6: 건설업 | BT6: 전기가스 및 공기조절공급업 | BU6: 도매 및 소매업 | BV6: 숙박 및 음식업 | BW6: 운수 및 창고업 | BX6: 금융 및 보험업 | BY6: 부동산업 | CC6: 계 | CD6: 자산운용회사2) | CE6: 신탁회사3) | CF6: 상호저축은행 | CG6: 신용협동조합 | CH6: 상호금융4) | CI6: 새마을금고 | CJ6: 기타5) | CL6: 계 | CM6: 신탁회사2) | CN6: 상호저축은행 | CO6: 신용협동조합 | CP6: 상호금융3) | CQ6: 새마을금고 | CR6: 기타4) | CU6: 대기업 | CV6: 중소기업 | CX6: (주택담보대출)3)
A7: 2019 | B7: 173388 | C7: 166463 | D7: 32472.22 | E7: 133990.49 | F7: 6924.42 | G7: 1980.94 | H7: 4417.58 | I7: 29.27 | J7: 496.63 | K7: 2019 | L7: 166463 | M7: 32472.22 | N7: 112.33 | O7: 235.6 | P7: 24156.1 | Q7: 4299.63 | R7: 3662.73 | S7: 5.83 | T7: 133990.49 | U7: 63465.91 | V7: 5344.73 | W7: 43034.83 | X7: 16722.75 | Y7: 1796.15 | Z7: 93.99 | AA7: 3532.13 | AB7: 2019 | AC7: 284951 | AD7: 277778.73 | AE7: 237279.77 | AF7: 26317.51 | AG7: 3298.51 | AH7: 3048.06 | AI7: 1955.97 | AJ7: 955.1 | AK7: 790.41 | AL7: 2127.78 | AM7: 65.46 | AN7: 1940.16 | AO7: 7172.36 | AP7: 2019 | AQ7: 284951 | AR7: 160063.05 | AS7: 120972.36 | AT7: 81136.91 | AU7: 3915.7 | AV7: 208021.75 | AW7: 76929.35 | AX7: 2019 | AY7: 284951 | AZ7: 160063.05 | BA7: 25945 | BB7: 134117.57 | BC7: 69518.11 | BD7: 64599.46 | BE7: 47.066889 | BF7: 2019 | BG7: 163979 | BH7: 77335 | BI7: 31871 | BJ7: 10748 | BK7: 4988 | BL7: 6873 | BM7: 12627 | BN7: 21113 | BO7: 6488 | BP7: 86645 | BQ7: 1062 | BR7: 383 | BS7: 4915 | BT7: 1835 | BU7: 16592 | BV7: 9388 | BW7: 5829 | BX7: 850 | BY7: 22797 | BZ7: 120972.36 | CA7: 284951 | CB7: 2019 | CC7: 263818 | CD7: 29663.84 | CE7: 43884.036 | CF7: 1401.08 | CG7: 20015.1 | CH7: 84546.348 | CI7: 71788.546 | CJ7: 12519.05 | CK7: 2019 | CL7: 141089 | CM7: 180.93423 | CN7: 1178.06 | CO7: 16220.2 | CP7: 66694.348 | CQ7: 54806.66 | CR7: 2008.7973 | CS7: 2019 | CT7: 37529.104 | CU7: 1350.29 | CV7: 36178.814 | CW7: 94915 | CX7: 31750
A8: 2020 | B8: 187168 | C8: 182316 | D8: 41330.45 | E8: 140985.44 | F8: 4852.07 | G8: 714.12 | H8: 3592.45 | I8: 71.79 | J8: 473.71 | K8: 2020 | L8: 182316 | M8: 41330.45 | N8: 237.02 | O8: 273.1 | P8: 31402.67 | Q8: 4784.82 | R8: 4628.36 | S8: 4.48 | T8: 140985.44 | U8: 57531.01 | V8: 5808.01 | W8: 52128.8 | X8: 20990.43 | Y8: 1774.94 | Z8: 84.24 | AA8: 2668.01 | AB8: 2020 | AC8: 304982 | AD8: 296985.34 | AE8: 255533.36 | AF8: 27792.57 | AG8: 2520.02 | AH8: 2884.05 | AI8: 2192.27 | AJ8: 827.52 | AK8: 624.31 | AL8: 2195.33 | AM8: 70.05 | AN8: 2345.86 | AO8: 7996.77 | AP8: 2020 | AQ8: 304982 | AR8: 172585.69 | AS8: 127786.23 | AT8: 82737.27 | AU8: 4610.17 | AV8: 224929.01 | AW8: 80053.12 | AX8: 2020 | AY8: 304982 | AZ8: 172585.69 | BA8: 26693 | BB8: 145893.3 | BC8: 78201.86 | BD8: 67691.44 | BE8: 47.836692 | BF8: 2020 | BG8: 177196 | BH8: 78621 | BI8: 31770 | BJ8: 11618 | BK8: 4486 | BL8: 7149 | BM8: 12760 | BN8: 21690 | BO8: 5759 | BP8: 98576 | BQ8: 1159 | BR8: 392 | BS8: 5282 | BT8: 1756 | BU8: 19160 | BV8: 11006 | BW8: 6388 | BX8: 1501 | BY8: 25101 | BZ8: 127786.23 | CA8: 304982 | CB8: 2020 | CC8: 273204 | CD8: 28076.968 | CE8: 45536.774 | CF8: 1390.82 | CG8: 21072.22 | CH8: 89726.018 | CI8: 74789.862 | CJ8: 12611.338 | CK8: 2020 | CL8: 150807 | CM8: 157.1567 | CN8: 1182.66 | CO8: 17158.25 | CP8: 71133.511 | CQ8: 59324.719 | CR8: 1850.704 | CS8: 2020 | CT8: 49680.946 | CU8: 1206.81 | CV8: 48474.136 | CW8: 93701 | CX8: 30127
A9: 2021 | B9: 199292 | C9: 193837 | D9: 44085.42 | E9: 149751.46 | F9: 5454.58 | G9: 962.04 | H9: 4072.5 | I9: 113.44 | J9: 306.6 | K9: 2021 | L9: 193837 | M9: 44085.42 | N9: 174.71 | O9: 245.7 | P9: 33669.4 | Q9: 5132.78 | R9: 4850.31 | S9: 12.52 | T9: 149751.46 | U9: 62799.81 | V9: 4561.77 | W9: 55176.36 | X9: 23154.94 | Y9: 1505.18 | Z9: 79.59 | AA9: 2473.81 | AB9: 2021 | AC9: 318560 | AD9: 309155.31 | AE9: 263545.81 | AF9: 31318.84 | AG9: 3001.28 | AH9: 2931.51 | AI9: 2393.89 | AJ9: 719.4 | AK9: 541.49 | AL9: 2095.46 | AM9: 65.59 | AN9: 2542.04 | AO9: 9404.57 | AP9: 2021 | AQ9: 318560 | AR9: 181534.38 | AS9: 132183.36 | AT9: 87334.31 | AU9: 4842.13 | AV9: 233374.83 | AW9: 85185.07 | AX9: 2021 | AY9: 318560 | AZ9: 181534.38 | BA9: 25757 | BB9: 155777.41 | BC9: 82011.62 | BD9: 73765.79 | BE9: 48.900493 | BF9: 2021 | BG9: 186377 | BH9: 79984 | BI9: 31572 | BJ9: 11460 | BK9: 4814 | BL9: 7255 | BM9: 12101 | BN9: 22231 | BO9: 5799 | BP9: 106392 | BQ9: 1087 | BR9: 335 | BS9: 5590 | BT9: 1551 | BU9: 21483 | BV9: 11811 | BW9: 7227 | BX9: 1371 | BY9: 26731 | BZ9: 132183.36 | CA9: 318560 | CB9: 2021 | CC9: 295512 | CD9: 29479.502 | CE9: 50965.736 | CF9: 1633.04 | CG9: 22484.67 | CH9: 92347.849 | CI9: 86101.199 | CJ9: 12500.004 | CK9: 2021 | CL9: 172193 | CM9: 178.26158 | CN9: 1802 | CO9: 19399.78 | CP9: 77164.894 | CQ9: 71635.144 | CR9: 2012.9203 | CS9: 2021 | CT9: 68336.135 | CU9: 1734.9 | CV9: 66601.235 | CW9: 96682 | CX9: 31167
A10: 2022 | B10: 226117 | C10: 219868 | D10: 38896.71 | E10: 180971.72 | F10: 6249.4 | G10: 329.38 | H10: 5859.26 | I10: 48.9 | J10: 11.86 | K10: 2022 | L10: 219868 | M10: 38896.71 | N10: 198.03 | O10: 206.28 | P10: 30277.01 | Q10: 4006.74 | R10: 4200.73 | S10: 7.92 | T10: 180971.72 | U10: 102882.82 | V10: 5602.1 | W10: 44819.6 | X10: 24953.03 | Y10: 1104.29 | Z10: 74.85 | AA10: 1535.03 | AB10: 2022 | AC10: 322684 | AD10: 312348.57 | AE10: 262758.37 | AF10: 33725.73 | AG10: 3074.89 | AH10: 3042.28 | AI10: 2709.63 | AJ10: 863.64 | AK10: 518.54 | AL10: 2312.26 | AM10: 28.28 | AN10: 3314.95 | AO10: 10335.21 | AP10: 2022 | AQ10: 322684 | AR10: 190110.69 | AS10: 127632.91 | AT10: 89115.16 | AU10: 4940.09 | AV10: 232740.63 | AW10: 89943.12 | AX10: 2022 | AY10: 322684 | AZ10: 190110.69 | BA10: 28206 | BB10: 161904.54 | BC10: 84410.01 | BD10: 77494.52 | BE10: 50.174332 | BF10: 2022 | BG10: 195051 | BH10: 82753 | BI10: 32395 | BJ10: 10010 | BK10: 4729 | BL10: 7769 | BM10: 12557 | BN10: 23188 | BO10: 5666 | BP10: 112298 | BQ10: 1167 | BR10: 324 | BS10: 6520 | BT10: 1847 | BU10: 22835 | BV10: 12472 | BW10: 7491 | BX10: 1735 | BY10: 26841 | BZ10: 127632.91 | CA10: 322684 | CB10: 2022 | CC10: 322211 | CD10: 24742.33 | CE10: 60679.099 | CF10: 1540.13 | CG10: 25772.04 | CH10: 98514.563 | CI10: 96892.653 | CJ10: 14070.185 | CK10: 2022 | CL10: 185230 | CM10: 239.65 | CN10: 1752.78 | CO10: 21996.22 | CP10: 81713.474 | CQ10: 77035.314 | CR10: 2492.5617 | CS10: 2022 | CT10: 84591.447 | CU10: 2700.1773 | CV10: 81891.27 | CW10: 93368 | CX10: 31976
A11: 2023 | B11: 238134 | C11: 230854 | D11: 40700.87 | E11: 190153.14 | F11: 7280.24 | G11: 379.51 | H11: 6694.35 | I11: 40.22 | J11: 166.16 | K11: 2023 | L11: 230854 | M11: 40700.87 | N11: 254.39 | O11: 204.48 | P11: 32468.29 | Q11: 3798.71 | R11: 3968.62 | S11: 6.38 | T11: 190153.14 | U11: 111040.84 | V11: 7816.91 | W11: 46170.68 | X11: 23433.48 | Y11: 1145.8 | Z11: 67.98 | AA11: 477.45 | AB11: 2023 | AC11: 331804 | AD11: 322191.1 | AE11: 269811.97 | AF11: 35740.19 | AG11: 2573.18 | AH11: 3392.9 | AI11: 3173.35 | AJ11: 831.92 | AK11: 568.63 | AL11: 2460.07 | AM11: 34.43 | AN11: 3604.46 | AO11: 9612.86 | AP11: 2023 | AQ11: 331804 | AR11: 198267.46 | AS11: 128431.83 | AT11: 94011.82 | AU11: 5104.71 | AV11: 233738.07 | AW11: 98065.93 | AX11: 2023 | AY11: 331804 | AZ11: 198267.46 | BA11: 30962 | BB11: 167304.57 | BC11: 83572.98 | BD11: 83731.56 | BE11: 50.42271 | BF11: 2023 | BG11: 203372 | BH11: 89447 | BI11: 37152 | BJ11: 10739 | BK11: 4905 | BL11: 8292 | BM11: 12671 | BN11: 25338 | BO11: 5562 | BP11: 113926 | BQ11: 1263 | BR11: 49 | BS11: 7068 | BT11: 1740 | BU11: 22264 | BV11: 13992 | BW11: 7606 | BX11: 1611 | BY11: 26763 | BZ11: 128431.83 | CA11: 331804 | CB11: 2023 | CC11: 340151 | CD11: 25057.769 | CE11: 69396.726 | CF11: 968.44 | CG11: 25722.43 | CH11: 105183.82 | CI11: 98365.544 | CJ11: 15456.274 | CK11: 2023 | CL11: 179113 | CM11: 285.26 | CN11: 1622.91 | CO11: 22125.58 | CP11: 82962.79 | CQ11: 70547.134 | CR11: 1569.3264 | CS11: 2023 | CT11: 85757.825 | CU11: 2294.28 | CV11: 83463.545 | CW11: 86180 | CX11: 30187
A12: 2024 | B12: 252796 | C12: 244068 | D12: 42840.71 | E12: 201227.42 | F12: 8727.45 | G12: 644.64 | H12: 7785.39 | I12: 21.63 | J12: 275.79 | K12: 2024 | L12: 244068 | M12: 42840.71 | N12: 231.9 | O12: 213.18 | P12: 34920.16 | Q12: 4133.26 | R12: 3333.32 | S12: 8.89 | T12: 201227.42 | U12: 118709.71 | V12: 7248.85 | W12: 48326.38 | X12: 25349.21 | Y12: 1130.7 | Z12: 61.6 | AA12: 400.97 | AB12: 2024 | AC12: 357517 | AD12: 348082.09 | AE12: 289469.88 | AF12: 39831.37 | AG12: 3513.45 | AH12: 2817.42 | AI12: 3393.73 | AJ12: 570.22 | AK12: 563.37 | AL12: 2840.61 | AM12: 432.2 | AN12: 4649.84 | AO12: 9434.91 | AP12: 2024 | AQ12: 357517 | AR12: 214058.17 | AS12: 136622.4 | AT12: 103080.9 | AU12: 6836.4 | AV12: 251926.06 | AW12: 105590.92 | AX12: 2024 | AY12: 357517 | AZ12: 214058.17 | BA12: 40200 | BB12: 173857.65 | BC12: 85634.04 | BD12: 88223.67 | BE12: 48.629198 | BF12: 2024 | BG12: 220894.54 | BH12: 101274.65 | BI12: 42290.07 | BJ12: 13455.54 | BK12: 5378.6 | BL12: 8440.21 | BM12: 15429.23 | BN12: 28547.6 | BO12: 5255.48 | BP12: 119620.04 | BQ12: 1382.92 | BR12: 935.47 | BS12: 7011.5 | BT12: 2054.59 | BU12: 23102.63 | BV12: 14325.16 | BW12: 8165.17 | BX12: 1235.45 | BY12: 28884.66 | BZ12: 136622.4 | CA12: 357517 | CB12: 2024 | CC12: 355451 | CD12: 27275.609 | CE12: 74699.275 | CF12: 1016.34 | CG12: 26022.596 | CH12: 109452.95 | CI12: 100826.01 | CJ12: 16158.219 | CK12: 2024 | CL12: 178363 | CM12: 161.36 | CN12: 1384.31 | CO12: 21076.728 | CP12: 85245.681 | CQ12: 68532.91 | CR12: 1962.0114 | CS12: 2024 | CT12: 89174.905 | CU12: 2673.64 | CV12: 86501.265 | CW12: 82474 | CX12: 31278
A13: 2025 | B13: 260695 | C13: 252417 | D13: 42180.97 | E13: 210236.32 | F13: 8278.23 | G13: 240.94 | H13: 7812.6 | I13: 64.33 | J13: 160.36 | K13: 2025 | L13: 252417 | M13: 42180.97 | N13: 204.23 | O13: 198.62 | P13: 34549.46 | Q13: 3857.03 | R13: 3363.62 | S13: 8.01 | T13: 210236.32 | U13: 118649.63 | V13: 8379.13 | W13: 51679.91 | X13: 30126.41 | Y13: 1117.03 | Z13: 55.58 | AA13: 228.63 | AB13: 2025 | AC13: 369293 | AD13: 358759.69 | AE13: 292144.65 | AF13: 47403.06 | AG13: 3218.91 | AH13: 2554.92 | AI13: 3351.22 | AJ13: 577.63 | AK13: 441.54 | AL13: 2749.27 | AM13: 288.83 | AN13: 6029.66 | AO13: 10532.88 | AP13: 2025 | AQ13: 369293 | AR13: 216889.3 | AS13: 145658.02 | AT13: 112878.69 | AU13: 6745.24 | AV13: 259983.64 | AW13: 109308.93 | AX13: 2025 | AY13: 369293 | AZ13: 216889.3 | BA13: 39593 | BB13: 177295.65 | BC13: 86176.96 | BD13: 91118.78 | BE13: 48.00948 | BF13: 2025 | BG13: 223634.56 | BH13: 102014.27 | BI13: 43200.97 | BJ13: 12621.85 | BK13: 4834.41 | BL13: 8135.55 | BM13: 15851.93 | BN13: 30316.78 | BO13: 4941 | BP13: 121620.2 | BQ13: 1405.62 | BR13: 273.71 | BS13: 7209.18 | BT13: 1253.94 | BU13: 23491.12 | BV13: 14629.03 | BW13: 8521.19 | BX13: 774.24 | BY13: 29725.35 | BZ13: 145658.02 | CA13: 369293 | CB13: 2025 | CC13: 369014 | CD13: 27099.894 | CE13: 83072.249 | CF13: 919.14 | CG13: 26729.845 | CH13: 112586.53 | CI13: 100800.37 | CJ13: 17805.981 | CK13: 2025 | CL13: 181314 | CM13: 124.84 | CN13: 844.9 | CO13: 20932.928 | CP13: 86794.299 | CQ13: 71039.995 | CR13: 1577.0375 | CS13: 2025 | CT13: 86811.618 | CU13: 2861.08 | CV13: 83950.538 | CW13: 86580 | CX13: 36912
A15: 2023.1 | B15: 226598 | C15: 220192 | D15: 38517.84 | E15: 181674.42 | F15: 6406.59 | G15: 403.62 | H15: 5879.14 | I15: 47.44 | J15: 76.39 | K15: 2023.1 | L15: 220192 | M15: 38517.84 | N15: 163.27 | O15: 192.4 | P15: 29209.65 | Q15: 4095.77 | R15: 4812.37 | S15: 44.38 | T15: 181674.42 | U15: 103208.96 | V15: 5555.96 | W15: 43814.73 | X15: 26579.26 | Y15: 1053.67 | Z15: 73.66 | AA15: 1388.18 | AB15: 2023.1 | AC15: 322620 | AD15: 312320.05 | AE15: 262597.34 | AF15: 33827.13 | AG15: 3201.57 | AH15: 2650.11 | AI15: 2752.37 | AJ15: 859.63 | AK15: 399.96 | AL15: 2262.56 | AM15: 49.12 | AN15: 3720.26 | AO15: 10299.97 | AP15: 2023.1 | AQ15: 322620 | AR15: 190287.11 | AS15: 127041.04 | AT15: 89391.6 | AU15: 5291.81 | AV15: 232363.76 | AW15: 90256.23 | AX15: 2023.1 | AY15: 322620 | AZ15: 190287.11 | BA15: 28282 | BB15: 162004.75 | BC15: 84504.38 | BD15: 77500.5 | BE15: 50.215346 | BF15: 2023.1 | BZ15: 127041.04 | CA15: 322620 | CB15: 2023.1 | CC15: 330800 | CD15: 25184.073 | CE15: 65161.467 | CF15: 1535.78 | CG15: 26546.73 | CH15: 98919.213 | CI15: 99280.258 | CJ15: 14172.479 | CK15: 2023.1 | CL15: 184473 | CM15: 239.61 | CN15: 1770.48 | CO15: 22136.52 | CP15: 81315.661 | CQ15: 76475.487 | CR15: 2535.2421 | CS15: 2023.1 | CT15: 84818.75 | CU15: 2754.7573 | CV15: 82063.992 | CW15: 92392 | CX15: 31674
A16: 2 | B16: 228854 | C16: 222377 | D16: 41381.2 | E16: 180995.47 | F16: 6476.19 | G16: 400.61 | H16: 5948.6 | I16: 45.77 | J16: 81.21 | K16: 2 | L16: 222377 | M16: 41381.2 | N16: 179.08 | O16: 197.39 | P16: 31166.31 | Q16: 4066.17 | R16: 5733.87 | S16: 38.38 | T16: 180995.47 | U16: 105066.5 | V16: 5649.11 | W16: 43949.31 | X16: 23834.64 | Y16: 1066.97 | Z16: 72.89 | AA16: 1356.05 | AB16: 2 | AC16: 322239 | AD16: 312085.56 | AE16: 262305.38 | AF16: 33679.73 | AG16: 3175.05 | AH16: 2572.58 | AI16: 2858.42 | AJ16: 917.64 | AK16: 451.01 | AL16: 2325.23 | AM16: 70.57 | AN16: 3729.95 | AO16: 10152.98 | AP16: 2 | AQ16: 322239 | AR16: 190272.24 | AS16: 126564.38 | AT16: 89422.79 | AU16: 5401.89 | AV16: 231930.08 | AW16: 90308.4 | AX16: 2 | AY16: 322239 | AZ16: 190272.24 | BA16: 28484 | BB16: 161787.52 | BC16: 84198.9 | BD16: 77588.65 | BE16: 50.207306 | BF16: 2 | BZ16: 126564.38 | CA16: 322239 | CB16: 2 | CC16: 333402 | CD16: 24825.379 | CE16: 65785.279 | CF16: 1484.21 | CG16: 26212.97 | CH16: 99406.261 | CI16: 101716.32 | CJ16: 13971.58 | CK16: 2 | CL16: 183945 | CM16: 248.94 | CN16: 1685.27 | CO16: 22332.56 | CP16: 80713.109 | CQ16: 76442.839 | CR16: 2522.2821 | CS16: 2 | CT16: 85179.925 | CU16: 2757.3473 | CV16: 82422.578 | CW16: 91552 | CX16: 31526
A17: 3 | B17: 229984 | C17: 223156 | D17: 39971.32 | E17: 183185.12 | F17: 6828.62 | G17: 381.46 | H17: 6325.25 | I17: 40.14 | J17: 81.77 | K17: 3 | L17: 223156 | M17: 39971.32 | N17: 163.84 | O17: 198.51 | P17: 30195.35 | Q17: 3982.71 | R17: 5361.99 | S17: 68.92 | T17: 183185.12 | U17: 104637.32 | V17: 5809.36 | W17: 46608.91 | X17: 24068.54 | Y17: 1087.47 | Z17: 72 | AA17: 901.52 | AB17: 3 | AC17: 320533 | AD17: 310732.7 | AE17: 261339.46 | AF17: 33078.59 | AG17: 3082.36 | AH17: 2666.15 | AI17: 2946.06 | AJ17: 959.92 | AK17: 463.85 | AL17: 2325.61 | AM17: 58.04 | AN17: 3812.66 | AO17: 9800.79 | AP17: 3 | AQ17: 320533 | AR17: 190412.88 | AS17: 124669.19 | AT17: 88428.66 | AU17: 5451.43 | AV17: 230059.89 | AW17: 90473.58 | AX17: 3 | AY17: 320533 | AZ17: 190412.88 | BA17: 28580 | BB17: 161832.57 | BC17: 83986.51 | BD17: 77846.03 | BE17: 50.488583 | BF17: 3 | BG17: 195864 | BH17: 83630 | BI17: 32651 | BJ17: 9878 | BK17: 5190 | BL17: 7687 | BM17: 12695 | BN17: 23552 | BO17: 5703 | BP17: 112235 | BQ17: 1164 | BR17: 323 | BS17: 6534 | BT17: 1731 | BU17: 22741 | BV17: 12878 | BW17: 7478 | BX17: 1640 | BY17: 26635 | BZ17: 124669.19 | CA17: 320533 | CB17: 3 | CC17: 338276 | CD17: 25062.981 | CE17: 65455.436 | CF17: 1427.38 | CG17: 26257.4 | CH17: 101717.88 | CI17: 103565.03 | CJ17: 14789.889 | CK17: 3 | CL17: 182748 | CM17: 243.29 | CN17: 1705.53 | CO17: 22353.3 | CP17: 80293.317 | CQ17: 75755.775 | CR17: 2396.7886 | CS17: 3 | CT17: 85147.221 | CU17: 2769.12 | CV17: 82378.101 | CW17: 90426 | CX17: 31187
A18: 4 | B18: 228551 | C18: 221450 | D18: 42084.09 | E18: 179366.11 | F18: 7100.81 | G18: 388.75 | H18: 6579 | I18: 51.82 | J18: 81.24 | K18: 4 | L18: 221450 | M18: 42084.09 | N18: 268.18 | O18: 200.99 | P18: 33005.91 | Q18: 4136.57 | R18: 4414.79 | S18: 57.65 | T18: 179366.11 | U18: 104998.75 | V18: 6055.07 | W18: 45708.66 | X18: 20653.6 | Y18: 1133.64 | Z18: 71.98 | AA18: 744.41 | AB18: 4 | AC18: 322070 | AD18: 312365.85 | AE18: 263035.07 | AF18: 32343.79 | AG18: 3208.86 | AH18: 3138.27 | AI18: 2975.79 | AJ18: 893.71 | AK18: 545.67 | AL18: 2310.58 | AM18: 59.13 | AN18: 3854.98 | AO18: 9704.19 | AP18: 4 | AQ18: 322070 | AR18: 192282.62 | AS18: 124322.03 | AT18: 88343.35 | AU18: 5465.36 | AV18: 230432.82 | AW18: 91637.2 | AX18: 4 | AY18: 322070 | AZ18: 192282.62 | BA18: 29179 | BB18: 163103.86 | BC18: 84267.17 | BD18: 78836.7 | BE18: 50.642363 | BF18: 4 | BZ18: 124322.03 | CA18: 322070 | CB18: 4 | CC18: 339027 | CD18: 24921.162 | CE18: 67011.998 | CF18: 1382.81 | CG18: 26361.56 | CH18: 102597.9 | CI18: 101697.15 | CJ18: 15054.418 | CK18: 4 | CL18: 182456 | CM18: 244.31 | CN18: 1644.65 | CO18: 22419.66 | CP18: 80419.432 | CQ18: 75338.155 | CR18: 2389.7923 | CS18: 4 | CT18: 85856.38 | CU18: 2760.5548 | CV18: 83095.825 | CW18: 89465 | CX18: 30856
A19: 5 | B19: 233862 | C19: 226393 | D19: 41717.99 | E19: 184674.97 | F19: 7469.09 | G19: 379 | H19: 6959.59 | I19: 49.33 | J19: 81.17 | K19: 5 | L19: 226393 | M19: 41717.99 | N19: 193.99 | O19: 192.39 | P19: 31650 | Q19: 4000.79 | R19: 5625.58 | S19: 55.24 | T19: 184674.97 | U19: 107565.44 | V19: 6310.08 | W19: 44770.52 | X19: 24115.37 | Y19: 1177.7 | Z19: 71.47 | AA19: 664.39 | AB19: 5 | AC19: 323669 | AD19: 313649.27 | AE19: 266062.06 | AF19: 31465.99 | AG19: 3207.15 | AH19: 2210.42 | AI19: 3066.47 | AJ19: 947.52 | AK19: 389.8 | AL19: 2306.18 | AM19: 82.06 | AN19: 3911.62 | AO19: 10019.54 | AP19: 5 | AQ19: 323669 | AR19: 194760.81 | AS19: 123299.22 | AT19: 87419.46 | AU19: 5608.75 | AV19: 230572.91 | AW19: 93095.91 | AX19: 5 | AY19: 323669 | AZ19: 194760.81 | BA19: 30558 | BB19: 164202.58 | BC19: 84373.03 | BD19: 79829.52 | BE19: 50.731636 | BF19: 5 | BZ19: 123299.22 | CA19: 323669 | CB19: 5 | CC19: 336889 | CD19: 24836.417 | CE19: 65469.802 | CF19: 1344.72 | CG19: 26213.16 | CH19: 102600.65 | CI19: 100813.63 | CJ19: 15610.619 | CK19: 5 | CL19: 181696 | CM19: 245.4 | CN19: 1740.54 | CO19: 22422.99 | CP19: 80029.041 | CQ19: 74872.403 | CR19: 2385.6258 | CS19: 5 | CT19: 85554.777 | CU19: 2776.0971 | CV19: 82778.68 | CW19: 89059 | CX19: 30838
A20: 6 | B20: 240208 | C20: 232897 | D20: 44310.46 | E20: 188586.9 | F20: 7311.21 | G20: 389.26 | H20: 6795.78 | I20: 45.01 | J20: 81.16 | K20: 6 | L20: 232897 | M20: 44310.46 | N20: 238.28 | O20: 198.41 | P20: 34104.59 | Q20: 3904.32 | R20: 5792.77 | S20: 72.09 | T20: 188586.9 | U20: 107922.37 | V20: 6581.88 | W20: 44771.32 | X20: 27409.96 | Y20: 1206.28 | Z20: 71.04 | AA20: 624.05 | AB20: 6 | AC20: 325287 | AD20: 315451.81 | AE20: 268201.83 | AF20: 31377.24 | AG20: 2952.65 | AH20: 2230.43 | AI20: 3035.49 | AJ20: 947.5 | AK20: 403.54 | AL20: 2266.26 | AM20: 71.68 | AN20: 3965.19 | AO20: 9835.45 | AP20: 6 | AQ20: 325287 | AR20: 196124.34 | AS20: 123784.42 | AT20: 88073.33 | AU20: 5378.53 | AV20: 230467.79 | AW20: 94819.49 | AX20: 6 | AY20: 325287 | AZ20: 196124.34 | BA20: 31168 | BB20: 164955.75 | BC20: 84410.3 | BD20: 80545.47 | BE20: 50.710834 | BF20: 6 | BG20: 201503 | BH20: 87268 | BI20: 34944 | BJ20: 11404 | BK20: 4703 | BL20: 7993 | BM20: 12320 | BN20: 24988 | BO20: 5635 | BP20: 114235 | BQ20: 1255 | BR20: 327 | BS20: 7138 | BT20: 1932 | BU20: 22556 | BV20: 13413 | BW20: 7524 | BX20: 1474 | BY20: 27130 | BZ20: 123784.42 | CA20: 325287 | CB20: 6 | CC20: 338241 | CD20: 25126.742 | CE20: 65978.512 | CF20: 1329.01 | CG20: 26061.87 | CH20: 103550.02 | CI20: 100695.58 | CJ20: 15499.266 | CK20: 6 | CL20: 180977 | CM20: 244.8 | CN20: 1688.99 | CO20: 22354.96 | CP20: 80819.916 | CQ20: 73836.773 | CR20: 2031.5603 | CS20: 6 | CT20: 85226.795 | CU20: 2402.38 | CV20: 82824.415 | CW20: 88662 | CX20: 30661
A21: 7 | B21: 239967 | C21: 232286 | D21: 42411.93 | E21: 189874.13 | F21: 7681.71 | G21: 311.83 | H21: 7253.29 | I21: 35.44 | J21: 81.15 | K21: 7 | L21: 232286 | M21: 42411.93 | N21: 165.18 | O21: 204.29 | P21: 32585.2 | Q21: 3983.62 | R21: 5407.84 | S21: 65.8 | T21: 189874.13 | U21: 110990.04 | V21: 6833.51 | W21: 44798.28 | X21: 25366.3 | Y21: 1221.59 | Z21: 70.73 | AA21: 593.68 | AB21: 7 | AC21: 327638 | AD21: 317860.73 | AE21: 269521.86 | AF21: 31892.22 | AG21: 2935.69 | AH21: 2533.06 | AI21: 3099.31 | AJ21: 939.11 | AK21: 413.99 | AL21: 2355.85 | AM21: 73.59 | AN21: 4096.05 | AO21: 9777.2 | AP21: 7 | AQ21: 327638 | AR21: 197588.27 | AS21: 124702.9 | AT21: 89103.02 | AU21: 5346.76 | AV21: 231948.69 | AW21: 95689.22 | AX21: 7 | AY21: 327638 | AZ21: 197588.27 | BA21: 31471 | BB21: 166116.71 | BC21: 84604.61 | BD21: 81512.17 | BE21: 50.701295 | BF21: 7 | BZ21: 124702.9 | CA21: 327638 | CB21: 7 | CC21: 331292 | CD21: 24375.075 | CE21: 64643.356 | CF21: 1326.81 | CG21: 26019.43 | CH21: 104215.3 | CI21: 94632.067 | CJ21: 16079.965 | CK21: 7 | CL21: 181613 | CM21: 235.28 | CN21: 1659.49 | CO21: 22370.41 | CP21: 81389.034 | CQ21: 73686.508 | CR21: 2272.2779 | CS21: 7 | CT21: 86032.333 | CU21: 2757.28 | CV21: 83275.053 | CW21: 88484 | CX21: 30686
A22: 8 | B22: 244083 | C22: 236304 | D22: 40542.14 | E22: 195762 | F22: 7779.99 | G22: 332.99 | H22: 7340.45 | I22: 25.36 | J22: 81.19 | K22: 8 | L22: 236304 | M22: 40542.14 | N22: 185.54 | O22: 197.93 | P22: 31246.61 | Q22: 4468.12 | R22: 4393.36 | S22: 50.58 | T22: 195762 | U22: 114373.41 | V22: 7046.19 | W22: 44114.21 | X22: 28368.84 | Y22: 1228.31 | Z22: 70.29 | AA22: 560.75 | AB22: 8 | AC22: 328611 | AD22: 318754.51 | AE22: 270032.8 | AF22: 32231.8 | AG22: 3086.03 | AH22: 2383.38 | AI22: 3158.08 | AJ22: 933.66 | AK22: 401.58 | AL22: 2417.61 | AM22: 58.51 | AN22: 4051.06 | AO22: 9856.05 | AP22: 8 | AQ22: 328611 | AR22: 198103.24 | AS22: 125399.58 | AT22: 89745.38 | AU22: 5107.74 | AV22: 232525.84 | AW22: 96084.75 | AX22: 8 | AY22: 328611 | AZ22: 198103.24 | BA22: 31515 | BB22: 166588.25 | BC22: 84481.61 | BD22: 82106.64 | BE22: 50.694666 | BF22: 8 | BZ22: 125399.58 | CA22: 328611 | CB22: 8 | CC22: 333518 | CD22: 25220.843 | CE22: 66101.409 | CF22: 1325.95 | CG22: 26127.41 | CH22: 103972.48 | CI22: 94721.772 | CJ22: 16048.133 | CK22: 8 | CL22: 181169 | CM22: 249.44 | CN22: 1673.23 | CO22: 22250.67 | CP22: 81612.797 | CQ22: 73224.447 | CR22: 2158.4164 | CS22: 8 | CT22: 85848.358 | CU22: 2756.13 | CV22: 83092.228 | CW22: 88344 | CX22: 30811
A23: 9 | B23: 246533 | C23: 238683 | D23: 40567.02 | E23: 198116.01 | F23: 7850.09 | G23: 316.62 | H23: 7412.44 | I23: 39.87 | J23: 81.16 | K23: 9 | L23: 238683 | M23: 40567.02 | N23: 334.28 | O23: 210.26 | P23: 32084.53 | Q23: 4234.3 | R23: 3652.35 | S23: 51.3 | T23: 198116.01 | U23: 112838.05 | V23: 7282.44 | W23: 46135.07 | X23: 30009.24 | Y23: 1240.84 | Z23: 69.79 | AA23: 540.58 | AB23: 9 | AC23: 330208 | AD23: 320496.85 | AE23: 270004.17 | AF23: 33499.49 | AG23: 2862.19 | AH23: 3062.89 | AI23: 3154.22 | AJ23: 925.5 | AK23: 500.92 | AL23: 2445.86 | AM23: 32.57 | AN23: 4009.04 | AO23: 9711.28 | AP23: 9 | AQ23: 330208 | AR23: 198954.47 | AS23: 126195.02 | AT23: 90970.46 | AU23: 5058.72 | AV23: 233414.61 | AW23: 96793.53 | AX23: 9 | AY23: 330208 | AZ23: 198954.47 | BA23: 31766 | BB23: 167188.12 | BC23: 84436.42 | BD23: 82751.64 | BE23: 50.631154 | BF23: 9 | BG23: 204013 | BH23: 89946 | BI23: 36449 | BJ23: 11407 | BK23: 5252 | BL23: 8235 | BM23: 12820 | BN23: 25158 | BO23: 5727 | BP23: 114065 | BQ23: 1263 | BR23: 56 | BS23: 7261 | BT23: 1779 | BU23: 22506 | BV23: 13714 | BW23: 7514 | BX23: 1506 | BY23: 27184 | BZ23: 126195.02 | CA23: 330208 | CB23: 9 | CC23: 336216 | CD23: 25080.596 | CE23: 66750.757 | CF23: 1313.39 | CG23: 26074.55 | CH23: 104826.68 | CI23: 96024.939 | CJ23: 16145.086 | CK23: 9 | CL23: 179723 | CM23: 280.08 | CN23: 1639.99 | CO23: 22118.48 | CP23: 81925.022 | CQ23: 72053.985 | CR23: 1705.4436 | CS23: 9 | CT23: 85094.01 | CU23: 2224.33 | CV23: 82869.68 | CW23: 87528 | CX23: 30526
A24: 10 | B24: 242571 | C24: 235217 | D24: 40144.02 | E24: 195072.48 | F24: 7353.59 | G24: 328.18 | H24: 6872.72 | I24: 70.97 | J24: 81.72 | K24: 10 | L24: 235217 | M24: 40144.02 | N24: 198.15 | O24: 207.33 | P24: 30782.87 | Q24: 3939.3 | R24: 4972.82 | S24: 43.55 | T24: 195072.48 | U24: 111048.91 | V24: 7423.34 | W24: 44851.64 | X24: 29941.28 | Y24: 1219.34 | Z24: 69.22 | AA24: 518.75 | AB24: 10 | AC24: 331194 | AD24: 321489.37 | AE24: 270318.82 | AF24: 34783.48 | AG24: 3123.47 | AH24: 2241.51 | AI24: 3160.18 | AJ24: 937.2 | AK24: 374.32 | AL24: 2452.07 | AM24: 72.34 | AN24: 4025.98 | AO24: 9704.41 | AP24: 10 | AQ24: 331194 | AR24: 198498.6 | AS24: 127588.82 | AT24: 92319.44 | AU24: 5106.38 | AV24: 234323.75 | AW24: 96870.03 | AX24: 10 | AY24: 331194 | AZ24: 198498.6 | BA24: 31023 | BB24: 167476.09 | BC24: 84511.7 | BD24: 82964.38 | BE24: 50.567368 | BF24: 10 | BZ24: 127588.82 | CA24: 331194 | CB24: 10 | CC24: 335975 | CD24: 25972.001 | CE24: 65728.43 | CF24: 1225.89 | CG24: 25765.39 | CH24: 104500.12 | CI24: 96744.123 | CJ24: 16039.046 | CK24: 10 | CL24: 180112 | CM24: 272.94 | CN24: 1609.13 | CO24: 21997.56 | CP24: 82698.11 | CQ24: 71433.62 | CR24: 2100.6401 | CS24: 10 | CT24: 85757.816 | CU24: 2711.48 | CV24: 83046.336 | CW24: 87267 | CX24: 30433
A25: 11 | B25: 241135 | C25: 233961 | D25: 38665.44 | E25: 195295.66 | F25: 7173.75 | G25: 344.94 | H25: 6674.9 | I25: 72.77 | J25: 81.14 | K25: 11 | L25: 233961 | M25: 38665.44 | N25: 163.68 | O25: 193.44 | P25: 30450.95 | Q25: 3854.75 | R25: 3969.15 | S25: 33.47 | T25: 195295.66 | U25: 113662.12 | V25: 7624.4 | W25: 44370.68 | X25: 27886.88 | Y25: 1182.12 | Z25: 68.38 | AA25: 501.08 | AB25: 11 | AC25: 333661 | AD25: 323767.7 | AE25: 272170.13 | AF25: 35053.59 | AG25: 3197.4 | AH25: 2261.31 | AI25: 3199.53 | AJ25: 931.14 | AK25: 382.71 | AL25: 2468.01 | AM25: 60.52 | AN25: 4043.36 | AO25: 9893.65 | AP25: 11 | AQ25: 333661 | AR25: 199970.14 | AS25: 128212.7 | AT25: 93068.07 | AU25: 5478.51 | AV25: 235784.66 | AW25: 97876.69 | AX25: 11 | AY25: 333661 | AZ25: 199970.14 | BA25: 31269 | BB25: 168700.72 | BC25: 84925.17 | BD25: 83775.55 | BE25: 50.560515 | BF25: 11 | BZ25: 128212.7 | CA25: 333661 | CB25: 11 | CC25: 338681 | CD25: 26088.832 | CE25: 68479.123 | CF25: 1069.22 | CG25: 25619.18 | CH25: 104003.17 | CI25: 97641.913 | CJ25: 15779.559 | CK25: 11 | CL25: 180155 | CM25: 293.27 | CN25: 1662.69 | CO25: 22106.71 | CP25: 82989.353 | CQ25: 70993.407 | CR25: 2109.5704 | CS25: 11 | CT25: 86472.188 | CU25: 2782.92 | CV25: 83689.268 | CW25: 86544 | CX25: 30171
A26: 12 | B26: 238134 | C26: 230854 | D26: 40700.87 | E26: 190153.14 | F26: 7280.24 | G26: 379.51 | H26: 6694.35 | I26: 40.22 | J26: 166.16 | K26: 12 | L26: 230854 | M26: 40700.87 | N26: 254.39 | O26: 204.48 | P26: 32468.29 | Q26: 3798.71 | R26: 3968.62 | S26: 6.38 | T26: 190153.14 | U26: 111040.84 | V26: 7816.91 | W26: 46170.68 | X26: 23433.48 | Y26: 1145.8 | Z26: 67.98 | AA26: 477.45 | AB26: 12 | AC26: 331804 | AD26: 322191.1 | AE26: 269811.97 | AF26: 35740.19 | AG26: 2573.18 | AH26: 3392.9 | AI26: 3173.35 | AJ26: 831.92 | AK26: 568.63 | AL26: 2460.07 | AM26: 34.43 | AN26: 3604.46 | AO26: 9612.86 | AP26: 12 | AQ26: 331804 | AR26: 198267.46 | AS26: 128431.83 | AT26: 94014.63 | AU26: 5104.71 | AV26: 233738.07 | AW26: 98065.93 | AX26: 12 | AY26: 331804 | AZ26: 198267.46 | BA26: 30962 | BB26: 167304.57 | BC26: 83572.98 | BD26: 83731.56 | BE26: 50.42271 | BF26: 12 | BG26: 203372 | BH26: 89447 | BI26: 37152 | BJ26: 10739 | BK26: 4905 | BL26: 8292 | BM26: 12671 | BN26: 25338 | BO26: 5562 | BP26: 113926 | BQ26: 1263 | BR26: 49 | BS26: 7068 | BT26: 1740 | BU26: 22264 | BV26: 13992 | BW26: 7606 | BX26: 1611 | BY26: 26763 | BZ26: 128431.83 | CA26: 331804 | CB26: 12 | CC26: 340151 | CD26: 25057.769 | CE26: 69396.726 | CF26: 968.44 | CG26: 25722.43 | CH26: 105183.82 | CI26: 98365.544 | CJ26: 15456.274 | CK26: 12 | CL26: 179113 | CM26: 285.26 | CN26: 1622.91 | CO26: 22125.58 | CP26: 82962.79 | CQ26: 70547.134 | CR26: 1569.3264 | CS26: 12 | CT26: 85757.825 | CU26: 2294.28 | CV26: 83463.545 | CW26: 86180 | CX26: 30187
A28: 2024.1 | B28: 235863 | C28: 228270 | D28: 40984.35 | E28: 187285.95 | F28: 7593.09 | G28: 348.76 | H28: 7013.07 | I28: 29.46 | J28: 201.8 | K28: 2024.1 | L28: 228270 | M28: 40984.35 | N28: 139.51 | O28: 198.82 | P28: 31712.79 | Q28: 4705.25 | R28: 4189.82 | S28: 38.16 | T28: 187285.95 | U28: 110050.27 | V28: 7878.96 | W28: 45515.59 | X28: 22184.06 | Y28: 1125.89 | Z28: 67.63 | AA28: 463.55 | AB28: 2024.1 | AC28: 333520 | AD28: 324058.97 | AE28: 271209.4 | AF28: 36298.38 | AG28: 3081.07 | AH28: 2797.64 | AI28: 3207.49 | AJ28: 807.59 | AK28: 448.33 | AL28: 2452.02 | AM28: 150.17 | AN28: 3606.88 | AO28: 9460.99 | AP28: 2024.1 | AQ28: 333520 | AR28: 198952.99 | AS28: 128782.35 | AT28: 94681.08 | AU28: 5784.63 | AV28: 234360.43 | AW28: 99159.5 | AX28: 2024.1 | AY28: 333520 | AZ28: 198952.99 | BA28: 31110 | BB28: 167843.4 | BC28: 83111.13 | BD28: 84732.33 | BE28: 50.324838 | BF28: 2024.1 | BZ28: 128782.35 | CA28: 333520 | CB28: 2024.1 | CC28: 344601 | CD28: 26193.556 | CE28: 71793.732 | CF28: 902.82 | CG28: 25780.96 | CH28: 105797.42 | CI28: 98428.601 | CJ28: 15703.911 | CK28: 2024.1 | CL28: 178701 | CM28: 276.18 | CN28: 1592.49 | CO28: 21977.25 | CP28: 83016.554 | CQ28: 69942.659 | CR28: 1895.8663 | CS28: 2024.1 | CT28: 86488.772 | CU28: 2641.29 | CV28: 83847.482 | CW28: 85170 | CX28: 29949
A29: 2 | B29: 241074 | C29: 233276 | D29: 44014.52 | E29: 189261.85 | F29: 7797.8 | G29: 402.06 | H29: 7166.36 | I29: 33.62 | J29: 195.76 | K29: 2 | L29: 233276 | M29: 44014.52 | N29: 194.24 | O29: 193.4 | P29: 34139.24 | Q29: 3833.02 | R29: 5613.23 | S29: 41.39 | T29: 189261.85 | U29: 111326.69 | V29: 5915.26 | W29: 47016.34 | X29: 23338.77 | Y29: 1144.9 | Z29: 66.78 | AA29: 453.11 | AB29: 2 | AC29: 333511 | AD29: 323988.18 | AE29: 270930.59 | AF29: 36112.7 | AG29: 3345.45 | AH29: 2290.36 | AI29: 3314.72 | AJ29: 968.02 | AK29: 389.52 | AL29: 2489 | AM29: 404.74 | AN29: 3743.08 | AO29: 9522.47 | AP29: 2 | AQ29: 333511 | AR29: 200116.73 | AS29: 128079.6 | AT29: 94506.04 | AU29: 5314.29 | AV29: 233291.91 | AW29: 100218.74 | AX29: 2 | AY29: 333511 | AZ29: 200116.73 | BA29: 32533 | BB29: 167583.85 | BC29: 83034.75 | BD29: 84549.16 | BE29: 50.248373 | BF29: 2 | BZ29: 128079.6 | CA29: 333511 | CB29: 2 | CC29: 346279 | CD29: 23789.052 | CE29: 74321.181 | CF29: 879.24 | CG29: 25792.3 | CH29: 106556.23 | CI29: 99312.233 | CJ29: 15628.761 | CK29: 2 | CL29: 178032 | CM29: 261.61 | CN29: 1595.79 | CO29: 21866.18 | CP29: 82934.807 | CQ29: 69381.957 | CR29: 1991.6556 | CS29: 2 | CT29: 86734.32 | CU29: 2748.41 | CV29: 83985.91 | CW29: 84321 | CX29: 29742
A30: 3 | B30: 246168 | C30: 237878 | D30: 45318.06 | E30: 192559.92 | F30: 8289.25 | G30: 488.75 | H30: 7569.19 | I30: 34.5 | J30: 196.81 | K30: 3 | L30: 237878 | M30: 45318.06 | N30: 200.82 | O30: 205.86 | P30: 35279.92 | Q30: 3968.84 | R30: 5600.93 | S30: 61.69 | T30: 192559.92 | U30: 114596.12 | V30: 5585.37 | W30: 47051.99 | X30: 23671.3 | Y30: 1142.03 | Z30: 66.43 | AA30: 446.68 | AB30: 3 | AC30: 334994 | AD30: 325551.15 | AE30: 272490.2 | AF30: 35365.45 | AG30: 3282.45 | AH30: 2774.83 | AI30: 3364.26 | AJ30: 1001.68 | AK30: 493.48 | AL30: 2577.94 | AM30: 344.58 | AN30: 3856.28 | AO30: 9443.09 | AP30: 3 | AQ30: 334994 | AR30: 202022.97 | AS30: 127595.97 | AT30: 94484.4 | AU30: 5375.33 | AV30: 233964.56 | AW30: 101029.71 | AX30: 3 | AY30: 334994 | AZ30: 202022.97 | BA30: 33635 | BB30: 168387.74 | BC30: 83506.35 | BD30: 84881.36 | BE30: 50.265897 | BF30: 3 | BG30: 207398.26 | BH30: 92369.94 | BI30: 39354 | BJ30: 11282.77 | BK30: 5258.38 | BL30: 8625.1 | BM30: 12709.84 | BN30: 26182.78 | BO30: 5544.31 | BP30: 115028.52 | BQ30: 1244.65 | BR30: 393.66 | BS30: 7149.75 | BT30: 1970.32 | BU30: 22314.35 | BV30: 13872.83 | BW30: 7572.53 | BX30: 1568.75 | BY30: 27069.5 | BZ30: 127595.97 | CA30: 334994 | CB30: 3 | CC30: 348657 | CD30: 24152.64 | CE30: 74204.745 | CF30: 882.64 | CG30: 25881.99 | CH30: 108252.37 | CI30: 99326.021 | CJ30: 15956.597 | CK30: 3 | CL30: 177535 | CM30: 251.07 | CN30: 1511.86 | CO30: 21722.39 | CP30: 83411.537 | CQ30: 68652.902 | CR30: 1985.2414 | CS30: 3 | CT30: 86952.312 | CU30: 2757.54 | CV30: 84194.772 | CW30: 83705 | CX30: 29578
A31: 4 | B31: 240581 | C31: 232045 | D31: 41497.67 | E31: 190547.46 | F31: 8535.23 | G31: 527.78 | H31: 7767.16 | I31: 44.54 | J31: 195.75 | K31: 4 | L31: 232045 | M31: 41497.67 | N31: 212.69 | O31: 211.76 | P31: 32619 | Q31: 3852.27 | R31: 4546.76 | S31: 55.19 | T31: 190547.46 | U31: 114515.59 | V31: 5778.06 | W31: 46209.7 | X31: 22370.48 | Y31: 1163.35 | Z31: 66.16 | AA31: 444.12 | AB31: 4 | AC31: 337570 | AD31: 328142.47 | AE31: 275598.81 | AF31: 35581.39 | AG31: 3467.82 | AH31: 2148.65 | AI31: 3348.52 | AJ31: 1041.78 | AK31: 393.5 | AL31: 2622.17 | AM31: 58.82 | AN31: 3881.01 | AO31: 9428.02 | AP31: 4 | AQ31: 337570 | AR31: 203445.68 | AS31: 128371.83 | AT31: 94984.58 | AU31: 5752.96 | AV31: 235975.21 | AW31: 101595.26 | AX31: 4 | AY31: 337570 | AZ31: 203445.68 | BA31: 33924 | BB31: 169522.19 | BC31: 84080.22 | BD31: 85442.06 | BE31: 50.218381 | BF31: 4 | BZ31: 128371.83 | CA31: 337570 | CB31: 4 | CC31: 347736 | CD31: 23836.325 | CE31: 72949.452 | CF31: 897.75 | CG31: 25821.44 | CH31: 108839.12 | CI31: 98919.464 | CJ31: 16472.451 | CK31: 4 | CL31: 177613 | CM31: 256.79 | CN31: 1503.16 | CO31: 21660.75 | CP31: 83633.457 | CQ31: 68412.049 | CR31: 2146.794 | CS31: 4 | CT31: 87623.149 | CU31: 2805.7 | CV31: 84817.449 | CW31: 83159 | CX31: 29242
A32: 5 | B32: 246213 | C32: 237500 | D32: 43326.6 | E32: 194173.48 | F32: 8712.47 | G32: 568.05 | H32: 7907.92 | I32: 40.87 | J32: 195.63 | K32: 5 | L32: 237500 | M32: 43326.6 | N32: 102.81 | O32: 191.92 | P32: 33224.95 | Q32: 3804.16 | R32: 5953.12 | S32: 49.64 | T32: 194173.48 | U32: 117508.53 | V32: 5964.3 | W32: 45562.61 | X32: 23439.89 | Y32: 1189.27 | Z32: 66.04 | AA32: 442.84 | AB32: 5 | AC32: 340003 | AD32: 330321.61 | AE32: 276309.38 | AF32: 36002.44 | AG32: 3551.1 | AH32: 2257.84 | AI32: 3392.57 | AJ32: 1026.18 | AK32: 437.61 | AL32: 2688.74 | AM32: 640.5 | AN32: 4015.25 | AO32: 9681.69 | AP32: 5 | AQ32: 340003 | AR32: 204786.09 | AS32: 129199.11 | AT32: 95719.95 | AU32: 6018.15 | AV32: 237861.46 | AW32: 102141.87 | AX32: 5 | AY32: 340003 | AZ32: 204786.09 | BA32: 34525 | BB32: 170260.65 | BC32: 84282.3 | BD32: 85978.3 | BE32: 50.07622 | BF32: 5 | BZ32: 129199.11 | CA32: 340003 | CB32: 5 | CC32: 349423 | CD32: 24328.063 | CE32: 73594.056 | CF32: 914.14 | CG32: 26015.81 | CH32: 109022.51 | CI32: 99012.895 | CJ32: 16535.527 | CK32: 5 | CL32: 177024 | CM32: 249.55 | CN32: 1335.82 | CO32: 21525.01 | CP32: 84005.925 | CQ32: 67862.76 | CR32: 2044.9355 | CS32: 5 | CT32: 87016.968 | CU32: 2800.88 | CV32: 84216.088 | CW32: 83243 | CX32: 29648
A33: 6 | B33: 251222 | C33: 241834 | D33: 43322.45 | E33: 198511.67 | F33: 9386.74 | G33: 678.55 | H33: 8418.65 | I33: 33.92 | J33: 255.62 | K33: 6 | L33: 241834 | M33: 43322.45 | N33: 252.37 | O33: 199.33 | P33: 34291.36 | Q33: 3703.74 | R33: 4806.81 | S33: 68.84 | T33: 198511.67 | U33: 119307.58 | V33: 6064.71 | W33: 46364.44 | X33: 25079.55 | Y33: 1194.54 | Z33: 65.69 | AA33: 435.16 | AB33: 6 | AC33: 345402 | AD33: 335738.9 | AE33: 281104.05 | AF33: 36337.43 | AG33: 3822.37 | AH33: 2900.55 | AI33: 3436.71 | AJ33: 679.73 | AK33: 541.49 | AL33: 2651.4 | AM33: 213.24 | AN33: 4051.93 | AO33: 9663.07 | AP33: 6 | AQ33: 345402 | AR33: 207953.9 | AS33: 131435.94 | AT33: 97648.63 | AU33: 6012.16 | AV33: 242931.67 | AW33: 102470.27 | AX33: 6 | AY33: 345402 | AZ33: 207953.9 | BA33: 36833 | BB33: 171121.16 | BC33: 85073.37 | BD33: 86047.73 | BE33: 49.542608 | BF33: 6 | BG33: 213966 | BH33: 96922 | BI33: 40332.28 | BJ33: 11745 | BK33: 5716 | BL33: 8680 | BM33: 14825 | BN33: 27062 | BO33: 5498 | BP33: 117043 | BQ33: 1294 | BR33: 691 | BS33: 7116 | BT33: 2062 | BU33: 22745 | BV33: 13931 | BW33: 7646 | BX33: 1448 | BY33: 27473 | BZ33: 131435.94 | CA33: 345402 | CB33: 6 | CC33: 348962 | CD33: 24391.74 | CE33: 72103.786 | CF33: 907.29 | CG33: 26147.81 | CH33: 109418.58 | CI33: 99111.835 | CJ33: 16880.962 | CK33: 6 | CL33: 176771 | CM33: 247.69 | CN33: 1345.88 | CO33: 21546.06 | CP33: 84394.661 | CQ33: 67521.177 | CR33: 1715.5323 | CS33: 6 | CT33: 87215.132 | CU33: 2522.01 | CV33: 84693.122 | CW33: 82872 | CX33: 29438
A34: 7 | B34: 247819 | C34: 238453 | D34: 42096.82 | E34: 196356.62 | F34: 9366.41 | G34: 684.14 | H34: 8395.3 | I34: 31.3 | J34: 255.67 | K34: 7 | L34: 238453 | M34: 42096.82 | N34: 120.26 | O34: 191.1 | P34: 34254.14 | Q34: 3755.91 | R34: 3718.48 | S34: 56.93 | T34: 196356.62 | U34: 119506.87 | V34: 6249.01 | W34: 47058 | X34: 21857.31 | Y34: 1191.63 | Z34: 65.17 | AA34: 428.63 | AB34: 7 | AC34: 346972 | AD34: 337369.7 | AE34: 282524.38 | AF34: 37112.48 | AG34: 3755.59 | AH34: 2318.14 | AI34: 3450.15 | AJ34: 636.15 | AK34: 386.85 | AL34: 2679.86 | AM34: 322.87 | AN34: 4183.23 | AO34: 9602.68 | AP34: 7 | AQ34: 346972 | AR34: 208848.99 | AS34: 132314.7 | AT34: 98749.41 | AU34: 5808.7 | AV34: 244235.2 | AW34: 102737.22 | AX34: 7 | AY34: 346972 | AZ34: 208848.99 | BA34: 37255 | BB34: 171593.85 | BC34: 85362.87 | BD34: 86231.01 | BE34: 49.454668 | BF34: 7 | BZ34: 132314.7 | CA34: 346972 | CB34: 7 | CC34: 354177 | CD34: 26783.393 | CE34: 73448.891 | CF34: 914.53 | CG34: 26290.31 | CH34: 109200.81 | CI34: 101026.77 | CJ34: 16512.302 | CK34: 7 | CL34: 176234 | CM34: 244.91 | CN34: 1355.86 | CO34: 21550.85 | CP34: 84625.829 | CQ34: 66441.994 | CR34: 2014.557 | CS34: 7 | CT34: 87400.729 | CU34: 2852.36 | CV34: 84548.369 | CW34: 82199 | CX34: 29384
A35: 8 | B35: 248008 | C35: 238910 | D35: 40893.16 | E35: 198016.83 | F35: 9097.51 | G35: 681.12 | H35: 8119.16 | I35: 41.61 | J35: 255.62 | K35: 8 | L35: 238910 | M35: 40893.16 | N35: 235.65 | O35: 194.72 | P35: 32818.76 | Q35: 3634.25 | R35: 3964.8 | S35: 44.98 | T35: 198016.83 | U35: 121712.97 | V35: 6441.53 | W35: 46521.74 | X35: 21653.88 | Y35: 1197.22 | Z35: 64.59 | AA35: 424.9 | AB35: 8 | AC35: 350440 | AD35: 340759.7 | AE35: 285537.98 | AF35: 38031.35 | AG35: 3549.2 | AH35: 2078.44 | AI35: 3450.16 | AJ35: 571.53 | AK35: 442.79 | AL35: 2749.39 | AM35: 139.25 | AN35: 4209.61 | AO35: 9680.05 | AP35: 8 | AQ35: 350440 | AR35: 211000.64 | AS35: 133805.31 | AT35: 100038.04 | AU35: 5633.77 | AV35: 246024.72 | AW35: 104414.99 | AX35: 8 | AY35: 350440 | AZ35: 211000.64 | BA35: 37519 | BB35: 173481.94 | BC35: 85848.53 | BD35: 87633.45 | BE35: 49.504035 | BF35: 8 | BZ35: 133805.31 | CA35: 350440 | CB35: 8 | CC35: 354905 | CD35: 26975.268 | CE35: 74316.753 | CF35: 921.46 | CG35: 26329.18 | CH35: 108978.97 | CI35: 100802.42 | CJ35: 16580.955 | CK35: 8 | CL35: 175959 | CM35: 225.9 | CN35: 1338.79 | CO35: 21640.54 | CP35: 84532.121 | CQ35: 66113.474 | CR35: 2108.1749 | CS35: 8 | CT35: 87509.078 | CU35: 2918.5 | CV35: 84590.578 | CW35: 81857 | CX35: 29264
A36: 9 | B36: 248075 | C36: 238764 | D36: 40300.77 | E36: 198463.44 | F36: 9311.21 | G36: 713.04 | H36: 8283.39 | I36: 39.17 | J36: 275.61 | K36: 9 | L36: 238764 | M36: 40300.77 | N36: 116.53 | O36: 184.29 | P36: 32743.54 | Q36: 3757.9 | R36: 3447.96 | S36: 50.55 | T36: 198463.44 | U36: 121689.81 | V36: 6719.39 | W36: 46432.4 | X36: 21936.49 | Y36: 1198.96 | Z36: 64.52 | AA36: 421.87 | AB36: 9 | AC36: 351426 | AD36: 341958.91 | AE36: 286190 | AF36: 38629.56 | AG36: 3452.98 | AH36: 2196.12 | AI36: 3448.35 | AJ36: 579.63 | AK36: 391.07 | AL36: 2787.16 | AM36: 58.74 | AN36: 4225.3 | AO36: 9466.98 | AP36: 9 | AQ36: 351426 | AR36: 211333.49 | AS36: 134515.19 | AT36: 100795.36 | AU36: 5577.15 | AV36: 246985.6 | AW36: 104440.25 | AX36: 9 | AY36: 351426 | AZ36: 211333.49 | BA36: 37773 | BB36: 173560.21 | BC36: 85917.42 | BD36: 87642.99 | BE36: 49.387413 | BF36: 9 | BG36: 216910.52 | BH36: 99351.25 | BI36: 41411.03 | BJ36: 12453.07 | BK36: 5434.92 | BL36: 8701.79 | BM36: 15638.14 | BN36: 27404.32 | BO36: 5872.53 | BP36: 117559.3 | BQ36: 1341.6 | BR36: 40.47 | BS36: 7369.89 | BT36: 2055.77 | BU36: 23114.77 | BV36: 14198.47 | BW36: 7827.95 | BX36: 1106.48 | BY36: 28013.99 | BZ36: 134515.19 | CA36: 351426 | CB36: 9 | CC36: 352451 | CD36: 27230.246 | CE36: 71677.271 | CF36: 940.01 | CG36: 26335.397 | CH36: 109190.81 | CI36: 100674.86 | CJ36: 16402.403 | CK36: 9 | CL36: 175800 | CM36: 185.7 | CN36: 1444.46 | CO36: 21460.154 | CP36: 84599.639 | CQ36: 66253.294 | CR36: 1856.7536 | CS36: 9 | CT36: 87704.699 | CU36: 2578.57 | CV36: 85126.129 | CW36: 81542 | CX36: 29770
A37: 10 | B37: 248217 | C37: 238997 | D37: 39781.43 | E37: 199216.03 | F37: 9219.91 | G37: 707.25 | H37: 8199.33 | I37: 37.64 | J37: 275.69 | K37: 10 | L37: 238997 | M37: 39781.43 | N37: 117.17 | O37: 203.32 | P37: 32369.26 | Q37: 3618.15 | R37: 3427.61 | S37: 45.92 | T37: 199216.03 | U37: 121673.56 | V37: 6929.15 | W37: 46385.05 | X37: 22550.95 | Y37: 1196.08 | Z37: 62.7 | AA37: 418.54 | AB37: 10 | AC37: 354472 | AD37: 344756.61 | AE37: 288234.3 | AF37: 39121.66 | AG37: 3617.06 | AH37: 2247.72 | AI37: 3446.82 | AJ37: 565.9 | AK37: 405.72 | AL37: 2815.12 | AM37: 44.92 | AN37: 4257.39 | AO37: 9714.89 | AP37: 10 | AQ37: 354472 | AR37: 212875.12 | AS37: 135277.48 | AT37: 101467.41 | AU37: 6318.88 | AV37: 249317.58 | AW37: 105153.88 | AX37: 10 | AY37: 354472 | AZ37: 212875.12 | BA37: 38589 | BB37: 174285.76 | BC37: 86326.78 | BD37: 87958.97 | BE37: 49.167709 | BF37: 10 | BZ37: 135277.48 | CA37: 354472 | CB37: 10 | CC37: 353811 | CD37: 26981.684 | CE37: 73295.339 | CF37: 968.78 | CG37: 26322.934 | CH37: 109516.49 | CI37: 100331.41 | CJ37: 16394.362 | CK37: 10 | CL37: 176924 | CM37: 185.17 | CN37: 1457.62 | CO37: 21210.168 | CP37: 84394.981 | CQ37: 67489.171 | CR37: 2186.89 | CS37: 10 | CT37: 88603.408 | CU37: 2848.71 | CV37: 85754.698 | CW37: 81802 | CX37: 30155
A38: 11 | B38: 247460 | C38: 238359 | D38: 39620.19 | E38: 198738.82 | F38: 9101.46 | G38: 679.43 | H38: 8104.4 | I38: 42.05 | J38: 275.58 | K38: 11 | L38: 238359 | M38: 39620.19 | N38: 203.83 | O38: 215.09 | P38: 32205.8 | Q38: 3643.51 | R38: 3317.82 | S38: 34.14 | T38: 198738.82 | U38: 121188.25 | V38: 7091.9 | W38: 46439.42 | X38: 22368.02 | Y38: 1175.84 | Z38: 62.05 | AA38: 413.34 | AB38: 11 | AC38: 357617 | AD38: 347913.96 | AE38: 290426.45 | AF38: 39532.94 | AG38: 3643.35 | AH38: 2254.67 | AI38: 3430.92 | AJ38: 587.92 | AK38: 508.57 | AL38: 2771.65 | AM38: 456.52 | AN38: 4300.97 | AO38: 9702.71 | AP38: 11 | AQ38: 357617 | AR38: 214782.77 | AS38: 136370.82 | AT38: 102600.76 | AU38: 6463.06 | AV38: 252289.96 | AW38: 105326.66 | AX38: 11 | AY38: 357617 | AZ38: 214782.77 | BA38: 39953 | BB38: 174829.95 | BC38: 86685.39 | BD38: 88144.54 | BE38: 48.887483 | BF38: 11 | BZ38: 136370.82 | CA38: 357617 | CB38: 11 | CC38: 355355 | CD38: 27738.619 | CE38: 74984.243 | CF38: 993.25 | CG38: 26209.501 | CH38: 109201.78 | CI38: 99871.725 | CJ38: 16355.883 | CK38: 11 | CL38: 177637 | CM38: 162.33 | CN38: 1461.91 | CO38: 20983.96 | CP38: 84569.362 | CQ38: 68287.381 | CR38: 2172.0576 | CS38: 11 | CT38: 88836.993 | CU38: 2921.44 | CV38: 85915.553 | CW38: 82198 | CX38: 30800
A39: 12 | B39: 252796 | C39: 244068 | D39: 42840.71 | E39: 201227.42 | F39: 8727.45 | G39: 644.64 | H39: 7785.39 | I39: 21.63 | J39: 275.79 | K39: 12 | L39: 244068 | M39: 42840.71 | N39: 231.9 | O39: 213.18 | P39: 34920.16 | Q39: 4133.26 | R39: 3333.32 | S39: 8.89 | T39: 201227.42 | U39: 118709.71 | V39: 7248.85 | W39: 48326.38 | X39: 25349.21 | Y39: 1130.7 | Z39: 61.6 | AA39: 400.97 | AB39: 12 | AC39: 357517 | AD39: 348082.09 | AE39: 289469.88 | AF39: 39831.37 | AG39: 3513.45 | AH39: 2817.42 | AI39: 3393.73 | AJ39: 570.22 | AK39: 563.37 | AL39: 2840.61 | AM39: 432.2 | AN39: 4649.84 | AO39: 9434.91 | AP39: 12 | AQ39: 357517 | AR39: 214058.17 | AS39: 136622.4 | AT39: 103080.9 | AU39: 6836.4 | AV39: 251926.06 | AW39: 105590.92 | AX39: 12 | AY39: 357517 | AZ39: 214058.17 | BA39: 40200 | BB39: 173857.65 | BC39: 85634.04 | BD39: 88223.67 | BE39: 48.629198 | BF39: 12 | BG39: 220894.54 | BH39: 101274.65 | BI39: 42290.07 | BJ39: 13455.54 | BK39: 5378.6 | BL39: 8440.21 | BM39: 15429.23 | BN39: 28547.6 | BO39: 5255.48 | BP39: 119620.04 | BQ39: 1382.92 | BR39: 935.47 | BS39: 7011.5 | BT39: 2054.59 | BU39: 23102.63 | BV39: 14325.16 | BW39: 8165.17 | BX39: 1235.45 | BY39: 28884.66 | BZ39: 136622.4 | CA39: 357517 | CB39: 12 | CC39: 355451 | CD39: 27275.609 | CE39: 74699.275 | CF39: 1016.34 | CG39: 26022.596 | CH39: 109452.95 | CI39: 100826.01 | CJ39: 16158.219 | CK39: 12 | CL39: 178363 | CM39: 161.36 | CN39: 1384.31 | CO39: 21076.728 | CP39: 85245.681 | CQ39: 68532.91 | CR39: 1962.0114 | CS39: 12 | CT39: 89174.905 | CU39: 2673.64 | CV39: 86501.265 | CW39: 82474 | CX39: 31278
A41: 2025.1 | B41: 249955 | C41: 241043 | D41: 42417.29 | E41: 198626.14 | F41: 8911.96 | G41: 585.72 | H41: 8019.28 | I41: 31.73 | J41: 275.23 | K41: 2025.1 | L41: 241043 | M41: 42417.29 | N41: 114.49 | O41: 215.93 | P41: 33977.51 | Q41: 4154.17 | R41: 3926.36 | S41: 28.83 | T41: 198626.14 | U41: 118272.97 | V41: 7090.72 | W41: 48725.12 | X41: 22970.18 | Y41: 1112.11 | Z41: 61.21 | AA41: 393.83 | AB41: 2025.1 | AC41: 357931 | AD41: 348448.82 | AE41: 288878.22 | AF41: 40295.55 | AG41: 3563.75 | AH41: 2611.7 | AI41: 3360.02 | AJ41: 621.29 | AK41: 423.34 | AL41: 2930.13 | AM41: 1179.91 | AN41: 4584.91 | AO41: 9482.54 | AP41: 2025.1 | AQ41: 357931 | AR41: 213410.99 | AS41: 136949.98 | AT41: 103880.05 | AU41: 7570.34 | AV41: 252189.62 | AW41: 105741.68 | AX41: 2025.1 | AY41: 357931 | AZ41: 213410.99 | BA41: 39519 | BB41: 173891.93 | BC41: 85569.74 | BD41: 88322.2 | BE41: 48.582528 | BF41: 2025.1 | BZ41: 136949.98 | CA41: 357931 | CB41: 2025.1 | CC41: 361107 | CD41: 29169.21 | CE41: 77300.303 | CF41: 1010.39 | CG41: 26073.344 | CH41: 109752.89 | CI41: 101346.02 | CJ41: 16454.839 | CK41: 2025.1 | CL41: 178248 | CM41: 155.81 | CN41: 1169.53 | CO41: 21149.793 | CP41: 85555.736 | CQ41: 68020.418 | CR41: 2196.7132 | CS41: 2025.1 | CT41: 89271.285 | CU41: 2859.43 | CV41: 86411.855 | CW41: 82314 | CX41: 31649
A42: 2 | B42: 255611 | C42: 246401 | D42: 43541.3 | E42: 202859.81 | F42: 9210.11 | G42: 525.51 | H42: 8387.39 | I42: 31.97 | J42: 265.24 | K42: 2 | L42: 246401 | M42: 43541.3 | N42: 113.62 | O42: 238.18 | P42: 35026.07 | Q42: 3958.46 | R42: 4169.34 | S42: 35.63 | T42: 202859.81 | U42: 120969 | V42: 7168.11 | W42: 48943.02 | X42: 24226.46 | Y42: 1103.76 | Z42: 60.87 | AA42: 388.59 | AB42: 2 | AC42: 359215 | AD42: 349667.16 | AE42: 288909.34 | AF42: 40944.13 | AG42: 3441.21 | AH42: 2855.75 | AI42: 3367.49 | AJ42: 612.01 | AK42: 436.25 | AL42: 2917.31 | AM42: 1448.21 | AN42: 4735.46 | AO42: 9548.24 | AP42: 2 | AQ42: 359215 | AR42: 213823.94 | AS42: 137495.77 | AT42: 104474.97 | AU42: 7895.75 | AV42: 253051.1 | AW42: 106164.32 | AX42: 2 | AY42: 359215 | AZ42: 213823.94 | BA42: 41013 | BB42: 172810.88 | BC42: 84941.65 | BD42: 87869.22 | BE42: 48.107924 | BF42: 2 | BZ42: 137495.77 | CA42: 359215 | CB42: 2 | CC42: 363301 | CD42: 29058.877 | CE42: 78756.717 | CF42: 999.85 | CG42: 26141.852 | CH42: 110067.34 | CI42: 101734.09 | CJ42: 16542.273 | CK42: 2 | CL42: 178332 | CM42: 151.04 | CN42: 1175.73 | CO42: 21187.486 | CP42: 85724.16 | CQ42: 67877.445 | CR42: 2216.1391 | CS42: 2 | CT42: 89353.796 | CU42: 2862.1 | CV42: 86491.696 | CW42: 82182 | CX42: 31758
A43: 3 | B43: 257710 | C43: 248544 | D43: 43390.2 | E43: 205153.62 | F43: 9166 | G43: 477.36 | H43: 8399.56 | I43: 24.01 | J43: 265.07 | K43: 3 | L43: 248544 | M43: 43390.2 | N43: 148.17 | O43: 227.82 | P43: 35980.46 | Q43: 3855.12 | R43: 3131.98 | S43: 46.65 | T43: 205153.62 | U43: 121295.26 | V43: 7293.79 | W43: 49170.74 | X43: 25843.95 | Y43: 1110.12 | Z43: 60.35 | AA43: 379.41 | AB43: 3 | AC43: 360165 | AD43: 350602.25 | AE43: 289078.11 | AF43: 41447.7 | AG43: 3152.55 | AH43: 2720.65 | AI43: 3419.6 | AJ43: 667.96 | AK43: 469.45 | AL43: 2934.07 | AM43: 1446.98 | AN43: 5265.18 | AO43: 9563.09 | AP43: 3 | AQ43: 360165 | AR43: 214130.26 | AS43: 137955.52 | AT43: 105143.43 | AU43: 8079.5 | AV43: 253956.84 | AW43: 106208.47 | AX43: 3 | AY43: 360165 | AZ43: 214130.26 | BA43: 41047 | BB43: 173082.58 | BC43: 85375.69 | BD43: 87706.99 | BE43: 48.056469 | BF43: 3 | BG43: 222209.62 | BH43: 100758.67 | BI43: 41871.51 | BJ43: 13772.18 | BK43: 5918.74 | BL43: 8446.92 | BM43: 15391.95 | BN43: 28298.79 | BO43: 4746.29 | BP43: 121451.12 | BQ43: 1382.9 | BR43: 1923.6 | BS43: 7304.76 | BT43: 1943.87 | BU43: 23155.87 | BV43: 14277.55 | BW43: 8244.47 | BX43: 839.21 | BY43: 29028.95 | BZ43: 137955.52 | CA43: 360165 | CB43: 3 | CC43: 365896 | CD43: 30810.082 | CE43: 78209.318 | CF43: 986.38 | CG43: 26397.5 | CH43: 110779.18 | CI43: 101730.5 | CJ43: 16983.036 | CK43: 3 | CL43: 178614 | CM43: 146.81 | CN43: 1119.97 | CO43: 21321.965 | CP43: 85831.076 | CQ43: 68070.777 | CR43: 2123.4024 | CS43: 3 | CT43: 89548.078 | CU43: 2870.6 | CV43: 86677.478 | CW43: 82132 | CX43: 32036
...

Sheet 1.4.어음부도율
A1: 4. 어음부도율1) 및 신설법인수
A2: (울산광역시) | H2: (백만원, %, 개)
A3: 연 월 | B3: 어음 교환액 | C3: 어음 부도액 | D3: 어음 부도율 | E3: 부도업체수2) | H3: 신설법인수
F4: 법인 | G4: 개인
A6: ='1.1. 한국은행 계정'!A11 -> 40544 | B6: 20522489 | C6: 19497 | D6: 0.1 | E6: 15 | F6: 6 | G6: 9 | H6: 1012
A7: ='1.1. 한국은행 계정'!A12 -> 40909 | B7: 21212276 | C7: 66000 | D7: 0.31 | E7: 9 | F7: 5 | G7: 4 | H7: 1204
A8: ='1.1. 한국은행 계정'!A13 -> 41275 | B8: 19893709 | C8: 23709 | D8: 0.12 | E8: 8 | F8: 7 | G8: 1 | H8: 1119
A9: ='1.1. 한국은행 계정'!A14 -> 41640 | B9: 20093572 | C9: 19188 | D9: 0.1 | E9: 7 | F9: 5 | G9: 2 | H9: 1179
A10: ='1.1. 한국은행 계정'!A15 -> 42005 | B10: 17763733 | C10: 16914 | D10: 0.1 | E10: 9 | F10: 6 | G10: 3 | H10: 1452
A11: ='1.1. 한국은행 계정'!A16 -> 42370 | B11: 16867836 | C11: 10075 | D11: 0.06 | E11: 6 | F11: 3 | G11: 3 | H11: 1416
A12: ='1.1. 한국은행 계정'!A17 -> 42736 | B12: 17574336 | C12: 32847 | D12: 0.19 | E12: 12 | F12: 10 | G12: 2 | H12: 1370
A13: ='1.1. 한국은행 계정'!A18 -> 43101 | B13: 17377957 | C13: 34320 | D13: 0.2 | E13: 8 | F13: 7 | G13: 1 | H13: 1346
A14: ='1.1. 한국은행 계정'!A19 -> 43466 | B14: 13780798 | C14: 45262 | D14: 0.33 | E14: 12 | F14: 9 | G14: 3 | H14: 1370
A15: ='1.1. 한국은행 계정'!A20 -> 43831 | B15: 10998234 | C15: 47845 | D15: 0.44 | E15: 9 | F15: 6 | G15: 3 | H15: 1615
A16: ='1.1. 한국은행 계정'!A21 -> 44197 | B16: 9441874 | C16: 32376 | D16: 0.34 | E16: 10 | F16: 10 | G16: 0 | H16: 1732
A17: ='1.1. 한국은행 계정'!A22 -> 44562 | B17: 13359027 | C17: 19298 | D17: 0.14 | E17: 2 | F17: 2 | G17: 0 | H17: 1496
... A20: ='1.1. 한국은행 계정'!A25 -> 45658 | B20: 9820316.8 | C20: 53675.693 | D20: 0.55 | E20: 1 | F20: 1 | G20: 0 | H20: 1217
A22: =DATE(YEAR(표지!O1)-2,MONTH(표지!O1)-1,1) -> 45352 | B22: 594890 | C22: 2053 | D22: 0.35 | E22: 0 | F22: 0 | G22: 0 | H22: 94
A23: =DATE(YEAR(A22),MONTH(A22)+1,1) -> 45383 | B23: 990484 | C23: 37 | D23: 0 | E23: 0 | F23: 0 | G23: 0 | H23: 97
A24: =DATE(YEAR(A23),MONTH(A23)+1,1) -> 45413 | B24: 681964 | C24: 1843 | D24: 0.27 | E24: 0 | F24: 0 | G24: 0 | H24: 112
A25: =DATE(YEAR(A24),MONTH(A24)+1,1) -> 45444 | B25: 371956 | C25: 696 | D25: 0.19 | E25: 0 | F25: 0 | G25: 0 | H25: 109
A26: =DATE(YEAR(A25),MONTH(A25)+1,1) -> 45474 | B26: 950991 | C26: 70 | D26: 0.01 | E26: 0 | F26: 0 | G26: 0 | H26: 106
A27: =DATE(YEAR(A26),MONTH(A26)+1,1) -> 45505 | B27: 474243 | C27: 18180 | D27: 3.83 | E27: 0 | F27: 0 | G27: 0 | H27: 79
A28: =DATE(YEAR(A27),MONTH(A27)+1,1) -> 45536 | B28: 491212 | C28: 1547 | D28: 0.31 | E28: 2 | F28: 2 | G28: 0 | H28: 83
A29: =DATE(YEAR(A28),MONTH(A28)+1,1) -> 45566 | B29: 911841 | C29: 4539 | D29: 0.5 | E29: 0 | F29: 0 | G29: 0 | H29: 117
A30: =DATE(YEAR(A29),MONTH(A29)+1,1) -> 45597 | B30: 547599 | C30: 155 | D30: 0.03 | E30: 0 | F30: 0 | G30: 0 | H30: 104
A31: =DATE(YEAR(A30),MONTH(A30)+1,1) -> 45627 | B31: 857555 | C31: 725 | D31: 0.08 | E31: 0 | F31: 0 | G31: 0 | H31: 96
A33: =DATE(YEAR(A31),MONTH(A31)+1,1) -> 45658 | B33: 723345 | C33: 237 | D33: 0.03 | E33: 0 | F33: 0 | G33: 0 | H33: 89
A34: =DATE(YEAR(A33),MONTH(A33)+1,1) -> 45689 | B34: 1015801 | C34: 243 | D34: 0.02 | E34: 0 | F34: 0 | G34: 0 | H34: 102
A35: =DATE(YEAR(A34),MONTH(A34)+1,1) -> 45717 | B35: 997584 | C35: 8082 | D35: 0.81 | E35: 0 | F35: 0 | G35: 0 | H35: 122
A36: =DATE(YEAR(A35),MONTH(A35)+1,1) -> 45748 | B36: 1003128 | C36: 7823 | D36: 0.78 | E36: 0 | F36: 0 | G36: 0 | H36: 104
A37: =DATE(YEAR(A36),MONTH(A36)+1,1) -> 45778 | B37: 886010 | C37: 15261 | D37: 1.72 | E37: 0 | F37: 0 | G37: 0 | H37: 100
A38: =DATE(YEAR(A37),MONTH(A37)+1,1) -> 45809 | B38: 536030 | C38: 1295 | D38: 0.24 | E38: 0 | F38: 0 | G38: 0 | H38: 108
A39: =DATE(YEAR(A38),MONTH(A38)+1,1) -> 45839 | B39: 616598 | C39: 1933 | D39: 0.31 | E39: 1 | F39: 1 | G39: 0 | H39: 97
A40: =DATE(YEAR(A39),MONTH(A39)+1,1) -> 45870 | B40: 792792 | C40: 5235 | D40: 0.66 | E40: 0 | F40: 0 | G40: 0 | H40: 94
A41: =DATE(YEAR(A40),MONTH(A40)+1,1) -> 45901 | B41: 910965 | C41: 10818 | D41: 1.19 | E41: 0 | F41: 0 | G41: 0 | H41: 102
A42: =DATE(YEAR(A41),MONTH(A41)+1,1) -> 45931 | B42: 788004 | C42: 759 | D42: 0.1 | E42: 0 | F42: 0 | G42: 0 | H42: 99
A43: =DATE(YEAR(A42),MONTH(A42)+1,1) -> 45962 | B43: 816265 | C43: 1961 | D43: 0.24 | E43: 0 | F43: 0 | G43: 0 | H43: 104
A44: =DATE(YEAR(A43),MONTH(A43)+1,1) -> 45992 | B44: 733796 | C44: 29 | D44: 0 | E44: 0 | F44: 0 | G44: 0 | H44: 96
A46: =DATE(YEAR(A44),MONTH(A44)+1,1) -> 46023 | B46: 879664 | C46: 0 | D46: 0 | E46: 0 | F46: 0 | G46: 0 | H46: 98
...

Sheet 2.1.제조업 생산·출하·재고지수
A1: Ⅰ- 2. 실물통계
A3: 1. 제조업 생산·출하·재고지수1)
A4: (울산광역시) | G4: (2020=100)
A5: 연월중 | B5: 생산지수 | D5: 출하지수 | F5: 재고지수2)
B6: 원지수 | C6: 계절변동 | D6: 원지수 | E6: 계절변동 | F6: 원지수 | G6: 계절변동
C7: 조정지수 | E7: 조정지수 | G7: 조정지수
A9: 40909 | B9: 120.052 | C9: - | D9: 114.33858 | E9: - | F9: 68.249917 | G9: -
A10: =DATE(YEAR(A9)+1,MONTH(A9),1) -> 41275 | B10: 117.65917 | C10: - | D10: 112.03142 | E10: - | F10: 65.811167 | G10: -
A11: =DATE(YEAR(A10)+1,MONTH(A10),1) -> 41640 | B11: 115.93225 | C11: - | D11: 111.34067 | E11: - | F11: 73.524833 | G11: -
A12: =DATE(YEAR(A11)+1,MONTH(A11),1) -> 42005 | B12: 112.2335 | C12: - | D12: 108.92325 | E12: - | F12: 74.626917 | G12: -
A13: =DATE(YEAR(A12)+1,MONTH(A12),1) -> 42370 | B13: 103.788 | C13: - | D13: 104.32083 | E13: - | F13: 80.883167 | G13: -
A14: =DATE(YEAR(A13)+1,MONTH(A13),1) -> 42736 | B14: 102.08575 | C14: - | D14: 103.48575 | E14: - | F14: 83.694 | G14: -
A15: =DATE(YEAR(A14)+1,MONTH(A14),1) -> 43101 | B15: 105.51817 | C15: - | D15: 104.57517 | E15: - | F15: 91.12575 | G15: -
